Workbook
Name grade: [1]임계풍속!$K$13
Name 설계번호: [2]환기량!$B$7
Name 젯트팬구경: [3]input!#REF!
Name 젯트팬구경: [3]input!#REF!
Name 젯트팬구경: [3]input!#REF!
Name 젯트팬구경: [3]input!#REF!
Name 중방향계수: [3]교통량!#REF!
Name 중방향계수: [3]교통량!#REF!
Name 중방향계수: [3]교통량!#REF!
Name 중방향계수: [3]교통량!#REF!

Sheet 환기량 산정
A1: 1. 환기량산출 설계조건 | F1: 노란색 | G1: 만 입력
A3: ◈ 터널명 | B3: 진북터널
A4: ◈ 도로구분 | B4: 해저터널
A6: 구 분 | B6: 마산 | C6: 방향 | D6: ⇒ | E6: 진주 | F6: 방향 | G6: =E6 -> 진주 | H6: 방향 | I6: =D6 -> ⇒ | J6: =B6 -> 마산 | K6: 방향
B7: 1구간 | C7: 2구간 | D7: 3구간 | E7: 4구간 | F7: 5구간 | G7: 1구간 | H7: 2구간 | I7: 3구간 | J7: 4구간 | K7: 5구간
A8: 터널구배 [%] | B8: 0 | G8: 1.784
A9: 터널길이 [m] | B9: 1000 | G9: 904.56
A10: 평균표고 [m] | B10: 0 | G10: 0
A11: 차선수 [N] | B11: 1 | G11: 2
A12: 구 분 | B12: 6구간 | C12: 7구간 | D12: 8구간 | E12: 9구간 | F12: 10구간 | G12: 6구간 | H12: 7구간 | I12: 8구간 | J12: 9구간 | K12: 10구간
A13: 터널구배 [%]
A14: 터널길이 [m]
A15: 평균표고 [m]
A16: 차선수 [N]
A17: 터널연장 [m] | C17: =B9+C9+D9+E9+F9+B14+C14+D14+E14+F14 -> 1000 | H17: =G9+H9+I9+J9+K9+G14+H14+I14+J14+K14 -> 904.56
A18: 터널내공단면적 [Ar] | C18: 58.67216 | D18: [ m2 ] | H18: =C18 -> 58.67216 | I18: [ m2 ]
A19: 터널둘레길이 [Lp] | C19: 29.728 | D19: [ m ] | H19: =C19 -> 29.728 | I19: [ m ]
A20: 터널대표직경(Dr=(4 * Ar)/Lp) | C20: 7.894531 | D20: [ m ] | H20: =ROUND(4*H18/H19,3) -> 7.895 | I20: [ m ]
A23: ◈ 설계속도(V) = | C23: 적용CODE | D23: =IF(D24=120,0.1,IF(D24=100,0.2,IF(D24=80,0.3))) -> 0.3 | F23: 120km : 0.1 | G23: 100km : 0.2 | H23: 80km : 0.3
B24: ( 단, 환기설계상 속도 = | D24: 80 | E24: (km/h )
A25: ◈ 서비스수준 | C25: 적용CODE | D25: =IF(D26="A",1,IF(D26="B",2,IF(D26="C",3,IF(D26="D",4,IF(D26="E",5,6))))) -> 4 | E25: 1 | F25: 2 | G25: 3 | H25: 4 | I25: 5 | J25: 6
C26: 서비스수준 | D26: D | E26: A | F26: B | G26: C | H26: D | I26: E | J26: F
B29: =IF(D25<=3,"첨두시교통량을 입력하세요","최대용량사용") -> 최대용량사용
A30: ◈ 첨두시교통량 | B30: =E6 -> 진주 | C30: 2200 | D30: 대/시 | I30: =1.4536*1.2 -> 1.74432 | J30: =1.2*60+I30 -> 73.74432
B31: =J6 -> 마산 | C31: 2200 | D31: 대/시
M33: 대형차통과대수
A34: 1) 추정교통량 | B34: =B6 -> 마산 | C34: =D6 -> ⇒ | D34: =E6 -> 진주 | E34: 구 간 | G34: 적용년도 | H34: 2222 | I34: 년 | J34: 내림차순(년도)으로 입력 | M34: =H38+I38+J38 -> 4214 | N34: =H46+I46+J46 -> 0 | O34: =H46+I46+J46 -> 0
A35: 목표년도 | C35: 일교통량 (대/일) | K35: 합 계 | L35: 대형차 | M35: 년도별 | R35: 17079
C36: 승용차 | E36: 버스 | I36: 트 럭 | L36: 혼입율 | M36: AADT비율 | R36: 11386
C37: 휘발유 | D37: 경유 | E37: 소형 | F37: 대형 | G37: 소형 | H37: 중형 | I37: 대형 | J37: 특수 | K37: (AADT) | L37: (Pt) | M37: (%) | R37: =R35+R36 -> 28465
A38: 2222 | C38: =I48*0.6 -> 49804.2 | D38: =I48*0.4 -> 33202.8 | E38: 0 | F38: 815 | G38: 14331 | H38: 3020 | I38: 332 | J38: 862 | K38: =SUM(C38:J38) -> 102367 | M38: =K38/K38 -> 1
B39: 차량별혼입율 | C39: =ROUND($C38/$K38*100,2) -> 48.65 | D39: =ROUND($D38/$K38*100,2) -> 32.44 | E39: =ROUND($E38/$K38*100,2) -> 0 | F39: =ROUND($F38/$K38*100,2) -> 0.8 | G39: =ROUND($G38/$K38*100,2) -> 14 | H39: =ROUND($H38/$K38*100,2) -> 2.95 | I39: =ROUND($I38/$K38*100,2) -> 0.32 | J39: =ROUND($J38/K38*100,2) -> 0.84 | K39: =SUM(C39:J39) -> 100 | L39: =ROUND(F39+H39+I39+J39,2) -> 4.91
K40: =SUM(C40:J40) -> 0 | M40: =K40/K38 -> 0
B41: 차량별혼입율 | C41: =ROUND($C40/$K40*100,2) -> #DIV/0! | D41: =ROUND($D40/$K40*100,2) -> #DIV/0! | E41: =ROUND($E40/$K40*100,2) -> #DIV/0! | F41: =ROUND($F40/$K40*100,2) -> #DIV/0! | G41: =ROUND($G40/$K40*100,2) -> #DIV/0! | H41: =ROUND($H40/$K40*100,2) -> #DIV/0! | I41: =ROUND($I40/$K40*100,2) -> #DIV/0! | J41: =ROUND($J40/K40*100,2) -> #DIV/0! | K41: =SUM(C41:J41) -> #DIV/0! | L41: =ROUND(F41+H41+I41+J41,2) -> #DIV/0!
K42: =SUM(C42:J42) -> 0 | M42: =K42/K38 -> 0
B43: 차량별혼입율 | C43: =ROUND($C42/$K42*100,2) -> #DIV/0! | D43: =ROUND($D42/$K42*100,2) -> #DIV/0! | E43: =ROUND($E42/$K42*100,2) -> #DIV/0! | F43: =ROUND($F42/$K42*100,2) -> #DIV/0! | G43: =ROUND($G42/$K42*100,2) -> #DIV/0! | H43: =ROUND($H42/$K42*100,2) -> #DIV/0! | I43: =ROUND($I42/$K42*100,2) -> #DIV/0! | J43: =ROUND($J42/K42*100,2) -> #DIV/0! | K43: =SUM(C43:J43) -> #DIV/0! | L43: =ROUND(F43+H43+I43+J43,2) -> #DIV/0!
K44: =SUM(C44:J44) -> 0 | M44: =K44/K38 -> 0
B45: 차량별혼입율 | C45: =ROUND($C44/$K44*100,2) -> #DIV/0! | D45: =ROUND($D44/$K44*100,2) -> #DIV/0! | E45: =ROUND($E44/$K44*100,2) -> #DIV/0! | F45: =ROUND($F44/$K44*100,2) -> #DIV/0! | G45: =ROUND($G44/$K44*100,2) -> #DIV/0! | H45: =ROUND($H44/$K44*100,2) -> #DIV/0! | I45: =ROUND($I44/$K44*100,2) -> #DIV/0! | J45: =ROUND($J44/K44*100,2) -> #DIV/0! | K45: =SUM(C45:J45) -> #DIV/0! | L45: =ROUND(F45+H45+I45+J45,2) -> #DIV/0!
K46: =SUM(C46:J46) -> 0 | M46: =K46/K38 -> 0
B47: 차량별혼입율 | C47: =ROUND($C46/$K46*100,2) -> #DIV/0! | D47: =ROUND($D46/$K46*100,2) -> #DIV/0! | E47: =ROUND($E46/$K46*100,2) -> #DIV/0! | F47: =ROUND($F46/$K46*100,2) -> #DIV/0! | G47: =ROUND($G46/$K46*100,2) -> #DIV/0! | H47: =ROUND($H46/$K46*100,2) -> #DIV/0! | I47: =ROUND($I46/$K46*100,2) -> #DIV/0! | J47: =ROUND($J46/K46*100,2) -> #DIV/0! | K47: =SUM(C47:J47) -> #DIV/0! | L47: =ROUND(F47+H47+I47+J47,2) -> #DIV/0!
...

Sheet PM보정계수
A2: 입자상물질 속도·경사보정계수 | Q2: 1. 입자상물질 속도·경사보정계수 산정
A4: (1) 승용차 / 휘발유 | Q4: 1.1 | R4: ='환기량 산정'!E6 -> 진주 | S4: 방향 | AB4: 1.2 | AC4: ='환기량 산정'!J6 -> 마산 | AD4: 방향
C5: 경사도(%) | Q5: (1.1-1) 승용차 / 휘발유 | AB5: (1.2-1) 승용차 / 휘발유 | AM5: 검증
A6: 차속 | B6: -100 | C6: -6 | D6: =(C6+E6)/2 -> -5 | E6: -4 | F6: =(E6+G6)/2 -> -3 | G6: -2 | H6: =(G6+I6)/2 -> -1 | I6: 0 | J6: =(I6+K6)/2 -> 1 | K6: 2 | L6: =(K6+M6)/2 -> 3 | M6: 4 | N6: =(M6+O6)/2 -> 5 | O6: 6 | Q6: 구간 | R6: 경사도(%) | S6: 10 | T6: 20 | U6: 30 | V6: 40 | W6: 50 | X6: 60 | Y6: 70 | Z6: 80 | AB6: 구간 | AC6: 경사도(%) | AD6: 10 | AE6: 20 | AF6: 30 | AG6: 40 | AH6: 50 | AI6: 60 | AJ6: 70 | AK6: 80 | AM6: 구분 | AN6: 10 | AO6: 20 | AP6: 30 | AQ6: 40 | AR6: 50 | AS6: 60 | AT6: 70 | AU6: 80
A7: 0 | B7: =C7 -> 0 | C7: 0 | D7: =(C7+E7)/2 -> 0 | E7: 0 | F7: =(E7+G7)/2 -> 0 | G7: 0 | H7: =(G7+I7)/2 -> 0 | I7: 0 | J7: =(I7+K7)/2 -> 0 | K7: 0 | L7: =(K7+M7)/2 -> 0 | M7: 0 | N7: =(M7+O7)/2 -> 0 | O7: 0 | Q7: 1구간 | R7: ='환기량 산정'!B8 -> 0 | S7: =HLOOKUP(INT($R7),$B$6:$O$17,3)+(HLOOKUP(INT($R7)+1,$B$6:$O$17,3)-HLOOKUP(INT($R7),$B$6:$O$17,3))*($R7-INT($R7)) -> 0.5 | T7: =HLOOKUP(INT($R7),$B$6:$O$17,4)+(HLOOKUP(INT($R7)+1,$B$6:$O$17,4)-HLOOKUP(INT($R7),$B$6:$O$17,4))*($R7-INT($R7)) -> 1 | U7: =HLOOKUP(INT($R7),$B$6:$O$17,5)+(HLOOKUP(INT($R7)+1,$B$6:$O$17,5)-HLOOKUP(INT($R7),$B$6:$O$17,5))*($R7-INT($R7)) -> 1 | V7: =HLOOKUP(INT($R7),$B$6:$O$17,6)+(HLOOKUP(INT($R7)+1,$B$6:$O$17,6)-HLOOKUP(INT($R7),$B$6:$O$17,6))*($R7-INT($R7)) -> 1 | W7: =HLOOKUP(INT($R7),$B$6:$O$17,7)+(HLOOKUP(INT($R7)+1,$B$6:$O$17,7)-HLOOKUP(INT($R7),$B$6:$O$17,7))*($R7-INT($R7)) -> 1 | X7: =HLOOKUP(INT($R7),$B$6:$O$17,8)+(HLOOKUP(INT($R7)+1,$B$6:$O$17,8)-HLOOKUP(INT($R7),$B$6:$O$17,8))*($R7-INT($R7)) -> 1.5 | Y7: =HLOOKUP(INT($R7),$B$6:$O$17,9)+(HLOOKUP(INT($R7)+1,$B$6:$O$17,9)-HLOOKUP(INT($R7),$B$6:$O$17,9))*($R7-INT($R7)) -> 1.5 | Z7: =HLOOKUP(INT($R7),$B$6:$O$17,10)+(HLOOKUP(INT($R7)+1,$B$6:$O$17,10)-HLOOKUP(INT($R7),$B$6:$O$17,10))*($R7-INT($R7)) -> 2.5 | AB7: 1구간 | AC7: ='환기량 산정'!G8 -> 1.784 | AD7: =HLOOKUP(INT($AC7),$B$6:$O$17,3)+(HLOOKUP(INT($AC7)+1,$B$6:$O$17,3)-HLOOKUP(INT($AC7),$B$6:$O$17,3))*($AC7-INT($AC7)) -> 0.946 | AE7: =HLOOKUP(INT($AC7),$B$6:$O$17,4)+(HLOOKUP(INT($AC7)+1,$B$6:$O$17,4)-HLOOKUP(INT($AC7),$B$6:$O$17,4))*($AC7-INT($AC7)) -> 1 | AF7: =HLOOKUP(INT($AC7),$B$6:$O$17,5)+(HLOOKUP(INT($AC7)+1,$B$6:$O$17,5)-HLOOKUP(INT($AC7),$B$6:$O$17,5))*($AC7-INT($AC7)) -> 1 | AG7: =HLOOKUP(INT($AC7),$B$6:$O$17,6)+(HLOOKUP(INT($AC7)+1,$B$6:$O$17,6)-HLOOKUP(INT($AC7),$B$6:$O$17,6))*($AC7-INT($AC7)) -> 1.446 | AH7: =HLOOKUP(INT($AC7),$B$6:$O$17,7)+(HLOOKUP(INT($AC7)+1,$B$6:$O$17,7)-HLOOKUP(INT($AC7),$B$6:$O$17,7))*($AC7-INT($AC7)) -> 1.446 | AI7: =HLOOKUP(INT($AC7),$B$6:$O$17,8)+(HLOOKUP(INT($AC7)+1,$B$6:$O$17,8)-HLOOKUP(INT($AC7),$B$6:$O$17,8))*($AC7-INT($AC7)) -> 1.946 | AJ7: =HLOOKUP(INT($AC7),$B$6:$O$17,9)+(HLOOKUP(INT($AC7)+1,$B$6:$O$17,9)-HLOOKUP(INT($AC7),$B$6:$O$17,9))*($AC7-INT($AC7)) -> 2.392 | AK7: =HLOOKUP(INT($AC7),$B$6:$O$17,10)+(HLOOKUP(INT($AC7)+1,$B$6:$O$17,10)-HLOOKUP(INT($AC7),$B$6:$O$17,10))*($AC7-INT($AC7)) -> 3.838 | AM7: 경사도(%) | AN7: 0 | AO7: =AN7 -> 0 | AP7: =AO7 -> 0 | AQ7: =AP7 -> 0 | AR7: =AQ7 -> 0 | AS7: =AR7 -> 0 | AT7: =AS7 -> 0 | AU7: =AT7 -> 0
A8: 10 | B8: =C8 -> 0.5 | C8: 0.5 | D8: =(C8+E8)/2 -> 0.5 | E8: 0.5 | F8: =(E8+G8)/2 -> 0.5 | G8: 0.5 | H8: =(G8+I8)/2 -> 0.5 | I8: 0.5 | J8: =(I8+K8)/2 -> 0.75 | K8: 1 | L8: =(K8+M8)/2 -> 1 | M8: 1 | N8: =(M8+O8)/2 -> 1 | O8: 1 | Q8: 2구간 | R8: ='환기량 산정'!C8 -> 0 | S8: =HLOOKUP(INT($R8),$B$6:$O$17,3)+(HLOOKUP(INT($R8)+1,$B$6:$O$17,3)-HLOOKUP(INT($R8),$B$6:$O$17,3))*($R8-INT($R8)) -> 0.5 | T8: =HLOOKUP(INT($R8),$B$6:$O$17,4)+(HLOOKUP(INT($R8)+1,$B$6:$O$17,4)-HLOOKUP(INT($R8),$B$6:$O$17,4))*($R8-INT($R8)) -> 1 | U8: =HLOOKUP(INT($R8),$B$6:$O$17,5)+(HLOOKUP(INT($R8)+1,$B$6:$O$17,5)-HLOOKUP(INT($R8),$B$6:$O$17,5))*($R8-INT($R8)) -> 1 | V8: =HLOOKUP(INT($R8),$B$6:$O$17,6)+(HLOOKUP(INT($R8)+1,$B$6:$O$17,6)-HLOOKUP(INT($R8),$B$6:$O$17,6))*($R8-INT($R8)) -> 1 | W8: =HLOOKUP(INT($R8),$B$6:$O$17,7)+(HLOOKUP(INT($R8)+1,$B$6:$O$17,7)-HLOOKUP(INT($R8),$B$6:$O$17,7))*($R8-INT($R8)) -> 1 | X8: =HLOOKUP(INT($R8),$B$6:$O$17,8)+(HLOOKUP(INT($R8)+1,$B$6:$O$17,8)-HLOOKUP(INT($R8),$B$6:$O$17,8))*($R8-INT($R8)) -> 1.5 | Y8: =HLOOKUP(INT($R8),$B$6:$O$17,9)+(HLOOKUP(INT($R8)+1,$B$6:$O$17,9)-HLOOKUP(INT($R8),$B$6:$O$17,9))*($R8-INT($R8)) -> 1.5 | Z8: =HLOOKUP(INT($R8),$B$6:$O$17,10)+(HLOOKUP(INT($R8)+1,$B$6:$O$17,10)-HLOOKUP(INT($R8),$B$6:$O$17,10))*($R8-INT($R8)) -> 2.5 | AB8: 2구간 | AC8: ='환기량 산정'!H8 -> 0 | AD8: =HLOOKUP(INT($AC8),$B$6:$O$17,3)+(HLOOKUP(INT($AC8)+1,$B$6:$O$17,3)-HLOOKUP(INT($AC8),$B$6:$O$17,3))*($AC8-INT($AC8)) -> 0.5 | AE8: =HLOOKUP(INT($AC8),$B$6:$O$17,4)+(HLOOKUP(INT($AC8)+1,$B$6:$O$17,4)-HLOOKUP(INT($AC8),$B$6:$O$17,4))*($AC8-INT($AC8)) -> 1 | AF8: =HLOOKUP(INT($AC8),$B$6:$O$17,5)+(HLOOKUP(INT($AC8)+1,$B$6:$O$17,5)-HLOOKUP(INT($AC8),$B$6:$O$17,5))*($AC8-INT($AC8)) -> 1 | AG8: =HLOOKUP(INT($AC8),$B$6:$O$17,6)+(HLOOKUP(INT($AC8)+1,$B$6:$O$17,6)-HLOOKUP(INT($AC8),$B$6:$O$17,6))*($AC8-INT($AC8)) -> 1 | AH8: =HLOOKUP(INT($AC8),$B$6:$O$17,7)+(HLOOKUP(INT($AC8)+1,$B$6:$O$17,7)-HLOOKUP(INT($AC8),$B$6:$O$17,7))*($AC8-INT($AC8)) -> 1 | AI8: =HLOOKUP(INT($AC8),$B$6:$O$17,8)+(HLOOKUP(INT($AC8)+1,$B$6:$O$17,8)-HLOOKUP(INT($AC8),$B$6:$O$17,8))*($AC8-INT($AC8)) -> 1.5 | AJ8: =HLOOKUP(INT($AC8),$B$6:$O$17,9)+(HLOOKUP(INT($AC8)+1,$B$6:$O$17,9)-HLOOKUP(INT($AC8),$B$6:$O$17,9))*($AC8-INT($AC8)) -> 1.5 | AK8: =HLOOKUP(INT($AC8),$B$6:$O$17,10)+(HLOOKUP(INT($AC8)+1,$B$6:$O$17,10)-HLOOKUP(INT($AC8),$B$6:$O$17,10))*($AC8-INT($AC8)) -> 2.5 | AM8: 보정계수 | AN8: =AN11+(AN13-AN11)*(AN7-AN10) -> 0.5 | AO8: =AO11+(AO13-AO11)*(AO7-AO10) -> 1 | AP8: =AP11+(AP13-AP11)*(AP7-AP10) -> 1 | AQ8: =AQ11+(AQ13-AQ11)*(AQ7-AQ10) -> 1 | AR8: =AR11+(AR13-AR11)*(AR7-AR10) -> 1 | AS8: =AS11+(AS13-AS11)*(AS7-AS10) -> 1.5 | AT8: =AT11+(AT13-AT11)*(AT7-AT10) -> 1.5 | AU8: =AU11+(AU13-AU11)*(AU7-AU10) -> 2.5
A9: 20 | B9: =C9 -> 0.5 | C9: 0.5 | D9: =(C9+E9)/2 -> 0.5 | E9: 0.5 | F9: =(E9+G9)/2 -> 0.5 | G9: 0.5 | H9: =(G9+I9)/2 -> 0.75 | I9: 1 | J9: =(I9+K9)/2 -> 1 | K9: 1 | L9: =(K9+M9)/2 -> 1 | M9: 1 | N9: =(M9+O9)/2 -> 1.25 | O9: 1.5 | Q9: 3구간 | R9: ='환기량 산정'!D8 -> 0 | S9: =HLOOKUP(INT($R9),$B$6:$O$17,3)+(HLOOKUP(INT($R9)+1,$B$6:$O$17,3)-HLOOKUP(INT($R9),$B$6:$O$17,3))*($R9-INT($R9)) -> 0.5 | T9: =HLOOKUP(INT($R9),$B$6:$O$17,4)+(HLOOKUP(INT($R9)+1,$B$6:$O$17,4)-HLOOKUP(INT($R9),$B$6:$O$17,4))*($R9-INT($R9)) -> 1 | U9: =HLOOKUP(INT($R9),$B$6:$O$17,5)+(HLOOKUP(INT($R9)+1,$B$6:$O$17,5)-HLOOKUP(INT($R9),$B$6:$O$17,5))*($R9-INT($R9)) -> 1 | V9: =HLOOKUP(INT($R9),$B$6:$O$17,6)+(HLOOKUP(INT($R9)+1,$B$6:$O$17,6)-HLOOKUP(INT($R9),$B$6:$O$17,6))*($R9-INT($R9)) -> 1 | W9: =HLOOKUP(INT($R9),$B$6:$O$17,7)+(HLOOKUP(INT($R9)+1,$B$6:$O$17,7)-HLOOKUP(INT($R9),$B$6:$O$17,7))*($R9-INT($R9)) -> 1 | X9: =HLOOKUP(INT($R9),$B$6:$O$17,8)+(HLOOKUP(INT($R9)+1,$B$6:$O$17,8)-HLOOKUP(INT($R9),$B$6:$O$17,8))*($R9-INT($R9)) -> 1.5 | Y9: =HLOOKUP(INT($R9),$B$6:$O$17,9)+(HLOOKUP(INT($R9)+1,$B$6:$O$17,9)-HLOOKUP(INT($R9),$B$6:$O$17,9))*($R9-INT($R9)) -> 1.5 | Z9: =HLOOKUP(INT($R9),$B$6:$O$17,10)+(HLOOKUP(INT($R9)+1,$B$6:$O$17,10)-HLOOKUP(INT($R9),$B$6:$O$17,10))*($R9-INT($R9)) -> 2.5 | AB9: 3구간 | AC9: ='환기량 산정'!I8 -> 0 | AD9: =HLOOKUP(INT($AC9),$B$6:$O$17,3)+(HLOOKUP(INT($AC9)+1,$B$6:$O$17,3)-HLOOKUP(INT($AC9),$B$6:$O$17,3))*($AC9-INT($AC9)) -> 0.5 | AE9: =HLOOKUP(INT($AC9),$B$6:$O$17,4)+(HLOOKUP(INT($AC9)+1,$B$6:$O$17,4)-HLOOKUP(INT($AC9),$B$6:$O$17,4))*($AC9-INT($AC9)) -> 1 | AF9: =HLOOKUP(INT($AC9),$B$6:$O$17,5)+(HLOOKUP(INT($AC9)+1,$B$6:$O$17,5)-HLOOKUP(INT($AC9),$B$6:$O$17,5))*($AC9-INT($AC9)) -> 1 | AG9: =HLOOKUP(INT($AC9),$B$6:$O$17,6)+(HLOOKUP(INT($AC9)+1,$B$6:$O$17,6)-HLOOKUP(INT($AC9),$B$6:$O$17,6))*($AC9-INT($AC9)) -> 1 | AH9: =HLOOKUP(INT($AC9),$B$6:$O$17,7)+(HLOOKUP(INT($AC9)+1,$B$6:$O$17,7)-HLOOKUP(INT($AC9),$B$6:$O$17,7))*($AC9-INT($AC9)) -> 1 | AI9: =HLOOKUP(INT($AC9),$B$6:$O$17,8)+(HLOOKUP(INT($AC9)+1,$B$6:$O$17,8)-HLOOKUP(INT($AC9),$B$6:$O$17,8))*($AC9-INT($AC9)) -> 1.5 | AJ9: =HLOOKUP(INT($AC9),$B$6:$O$17,9)+(HLOOKUP(INT($AC9)+1,$B$6:$O$17,9)-HLOOKUP(INT($AC9),$B$6:$O$17,9))*($AC9-INT($AC9)) -> 1.5 | AK9: =HLOOKUP(INT($AC9),$B$6:$O$17,10)+(HLOOKUP(INT($AC9)+1,$B$6:$O$17,10)-HLOOKUP(INT($AC9),$B$6:$O$17,10))*($AC9-INT($AC9)) -> 2.5
A10: 30 | B10: =C10 -> 0.5 | C10: 0.5 | D10: =(C10+E10)/2 -> 0.5 | E10: 0.5 | F10: =(E10+G10)/2 -> 0.5 | G10: 0.5 | H10: =(G10+I10)/2 -> 0.75 | I10: 1 | J10: =(I10+K10)/2 -> 1 | K10: 1 | L10: =(K10+M10)/2 -> 1.25 | M10: 1.5 | N10: =(M10+O10)/2 -> 1.75 | O10: 2 | Q10: 4구간 | R10: ='환기량 산정'!E8 -> 0 | S10: =HLOOKUP(INT($R10),$B$6:$O$17,3)+(HLOOKUP(INT($R10)+1,$B$6:$O$17,3)-HLOOKUP(INT($R10),$B$6:$O$17,3))*($R10-INT($R10)) -> 0.5 | T10: =HLOOKUP(INT($R10),$B$6:$O$17,4)+(HLOOKUP(INT($R10)+1,$B$6:$O$17,4)-HLOOKUP(INT($R10),$B$6:$O$17,4))*($R10-INT($R10)) -> 1 | U10: =HLOOKUP(INT($R10),$B$6:$O$17,5)+(HLOOKUP(INT($R10)+1,$B$6:$O$17,5)-HLOOKUP(INT($R10),$B$6:$O$17,5))*($R10-INT($R10)) -> 1 | V10: =HLOOKUP(INT($R10),$B$6:$O$17,6)+(HLOOKUP(INT($R10)+1,$B$6:$O$17,6)-HLOOKUP(INT($R10),$B$6:$O$17,6))*($R10-INT($R10)) -> 1 | W10: =HLOOKUP(INT($R10),$B$6:$O$17,7)+(HLOOKUP(INT($R10)+1,$B$6:$O$17,7)-HLOOKUP(INT($R10),$B$6:$O$17,7))*($R10-INT($R10)) -> 1 | X10: =HLOOKUP(INT($R10),$B$6:$O$17,8)+(HLOOKUP(INT($R10)+1,$B$6:$O$17,8)-HLOOKUP(INT($R10),$B$6:$O$17,8))*($R10-INT($R10)) -> 1.5 | Y10: =HLOOKUP(INT($R10),$B$6:$O$17,9)+(HLOOKUP(INT($R10)+1,$B$6:$O$17,9)-HLOOKUP(INT($R10),$B$6:$O$17,9))*($R10-INT($R10)) -> 1.5 | Z10: =HLOOKUP(INT($R10),$B$6:$O$17,10)+(HLOOKUP(INT($R10)+1,$B$6:$O$17,10)-HLOOKUP(INT($R10),$B$6:$O$17,10))*($R10-INT($R10)) -> 2.5 | AB10: 4구간 | AC10: ='환기량 산정'!J8 -> 0 | AD10: =HLOOKUP(INT($AC10),$B$6:$O$17,3)+(HLOOKUP(INT($AC10)+1,$B$6:$O$17,3)-HLOOKUP(INT($AC10),$B$6:$O$17,3))*($AC10-INT($AC10)) -> 0.5 | AE10: =HLOOKUP(INT($AC10),$B$6:$O$17,4)+(HLOOKUP(INT($AC10)+1,$B$6:$O$17,4)-HLOOKUP(INT($AC10),$B$6:$O$17,4))*($AC10-INT($AC10)) -> 1 | AF10: =HLOOKUP(INT($AC10),$B$6:$O$17,5)+(HLOOKUP(INT($AC10)+1,$B$6:$O$17,5)-HLOOKUP(INT($AC10),$B$6:$O$17,5))*($AC10-INT($AC10)) -> 1 | AG10: =HLOOKUP(INT($AC10),$B$6:$O$17,6)+(HLOOKUP(INT($AC10)+1,$B$6:$O$17,6)-HLOOKUP(INT($AC10),$B$6:$O$17,6))*($AC10-INT($AC10)) -> 1 | AH10: =HLOOKUP(INT($AC10),$B$6:$O$17,7)+(HLOOKUP(INT($AC10)+1,$B$6:$O$17,7)-HLOOKUP(INT($AC10),$B$6:$O$17,7))*($AC10-INT($AC10)) -> 1 | AI10: =HLOOKUP(INT($AC10),$B$6:$O$17,8)+(HLOOKUP(INT($AC10)+1,$B$6:$O$17,8)-HLOOKUP(INT($AC10),$B$6:$O$17,8))*($AC10-INT($AC10)) -> 1.5 | AJ10: =HLOOKUP(INT($AC10),$B$6:$O$17,9)+(HLOOKUP(INT($AC10)+1,$B$6:$O$17,9)-HLOOKUP(INT($AC10),$B$6:$O$17,9))*($AC10-INT($AC10)) -> 1.5 | AK10: =HLOOKUP(INT($AC10),$B$6:$O$17,10)+(HLOOKUP(INT($AC10)+1,$B$6:$O$17,10)-HLOOKUP(INT($AC10),$B$6:$O$17,10))*($AC10-INT($AC10)) -> 2.5 | AM10: 참고조건1 | AN10: =INT(AN7) -> 0 | AO10: =INT(AO7) -> 0 | AP10: =INT(AP7) -> 0 | AQ10: =INT(AQ7) -> 0 | AR10: =INT(AR7) -> 0 | AS10: =INT(AS7) -> 0 | AT10: =INT(AT7) -> 0 | AU10: =INT(AU7) -> 0
A11: 40 | B11: =C11 -> 1 | C11: 1 | D11: =(C11+E11)/2 -> 1 | E11: 1 | F11: =(E11+G11)/2 -> 1 | G11: 1 | H11: =(G11+I11)/2 -> 1 | I11: 1 | J11: =(I11+K11)/2 -> 1.25 | K11: 1.5 | L11: =(K11+M11)/2 -> 1.75 | M11: 2 | N11: =(M11+O11)/2 -> 2.25 | O11: 2.5 | Q11: 5구간 | R11: ='환기량 산정'!F8 -> 0 | S11: =HLOOKUP(INT($R11),$B$6:$O$17,3)+(HLOOKUP(INT($R11)+1,$B$6:$O$17,3)-HLOOKUP(INT($R11),$B$6:$O$17,3))*($R11-INT($R11)) -> 0.5 | T11: =HLOOKUP(INT($R11),$B$6:$O$17,4)+(HLOOKUP(INT($R11)+1,$B$6:$O$17,4)-HLOOKUP(INT($R11),$B$6:$O$17,4))*($R11-INT($R11)) -> 1 | U11: =HLOOKUP(INT($R11),$B$6:$O$17,5)+(HLOOKUP(INT($R11)+1,$B$6:$O$17,5)-HLOOKUP(INT($R11),$B$6:$O$17,5))*($R11-INT($R11)) -> 1 | V11: =HLOOKUP(INT($R11),$B$6:$O$17,6)+(HLOOKUP(INT($R11)+1,$B$6:$O$17,6)-HLOOKUP(INT($R11),$B$6:$O$17,6))*($R11-INT($R11)) -> 1 | W11: =HLOOKUP(INT($R11),$B$6:$O$17,7)+(HLOOKUP(INT($R11)+1,$B$6:$O$17,7)-HLOOKUP(INT($R11),$B$6:$O$17,7))*($R11-INT($R11)) -> 1 | X11: =HLOOKUP(INT($R11),$B$6:$O$17,8)+(HLOOKUP(INT($R11)+1,$B$6:$O$17,8)-HLOOKUP(INT($R11),$B$6:$O$17,8))*($R11-INT($R11)) -> 1.5 | Y11: =HLOOKUP(INT($R11),$B$6:$O$17,9)+(HLOOKUP(INT($R11)+1,$B$6:$O$17,9)-HLOOKUP(INT($R11),$B$6:$O$17,9))*($R11-INT($R11)) -> 1.5 | Z11: =HLOOKUP(INT($R11),$B$6:$O$17,10)+(HLOOKUP(INT($R11)+1,$B$6:$O$17,10)-HLOOKUP(INT($R11),$B$6:$O$17,10))*($R11-INT($R11)) -> 2.5 | AB11: 5구간 | AC11: ='환기량 산정'!K8 -> 0 | AD11: =HLOOKUP(INT($AC11),$B$6:$O$17,3)+(HLOOKUP(INT($AC11)+1,$B$6:$O$17,3)-HLOOKUP(INT($AC11),$B$6:$O$17,3))*($AC11-INT($AC11)) -> 0.5 | AE11: =HLOOKUP(INT($AC11),$B$6:$O$17,4)+(HLOOKUP(INT($AC11)+1,$B$6:$O$17,4)-HLOOKUP(INT($AC11),$B$6:$O$17,4))*($AC11-INT($AC11)) -> 1 | AF11: =HLOOKUP(INT($AC11),$B$6:$O$17,5)+(HLOOKUP(INT($AC11)+1,$B$6:$O$17,5)-HLOOKUP(INT($AC11),$B$6:$O$17,5))*($AC11-INT($AC11)) -> 1 | AG11: =HLOOKUP(INT($AC11),$B$6:$O$17,6)+(HLOOKUP(INT($AC11)+1,$B$6:$O$17,6)-HLOOKUP(INT($AC11),$B$6:$O$17,6))*($AC11-INT($AC11)) -> 1 | AH11: =HLOOKUP(INT($AC11),$B$6:$O$17,7)+(HLOOKUP(INT($AC11)+1,$B$6:$O$17,7)-HLOOKUP(INT($AC11),$B$6:$O$17,7))*($AC11-INT($AC11)) -> 1 | AI11: =HLOOKUP(INT($AC11),$B$6:$O$17,8)+(HLOOKUP(INT($AC11)+1,$B$6:$O$17,8)-HLOOKUP(INT($AC11),$B$6:$O$17,8))*($AC11-INT($AC11)) -> 1.5 | AJ11: =HLOOKUP(INT($AC11),$B$6:$O$17,9)+(HLOOKUP(INT($AC11)+1,$B$6:$O$17,9)-HLOOKUP(INT($AC11),$B$6:$O$17,9))*($AC11-INT($AC11)) -> 1.5 | AK11: =HLOOKUP(INT($AC11),$B$6:$O$17,10)+(HLOOKUP(INT($AC11)+1,$B$6:$O$17,10)-HLOOKUP(INT($AC11),$B$6:$O$17,10))*($AC11-INT($AC11)) -> 2.5 | AM11: 참고값1 | AN11: =HLOOKUP(AN10,$B$6:$O$17,AN14) -> 0.5 | AO11: =HLOOKUP(AO10,$B$6:$O$17,AO14) -> 1 | AP11: =HLOOKUP(AP10,$B$6:$O$17,AP14) -> 1 | AQ11: =HLOOKUP(AQ10,$B$6:$O$17,AQ14) -> 1 | AR11: =HLOOKUP(AR10,$B$6:$O$17,AR14) -> 1 | AS11: =HLOOKUP(AS10,$B$6:$O$17,AS14) -> 1.5 | AT11: =HLOOKUP(AT10,$B$6:$O$17,AT14) -> 1.5 | AU11: =HLOOKUP(AU10,$B$6:$O$17,AU14) -> 2.5
A12: 50 | B12: =C12 -> 1 | C12: 1 | D12: =(C12+E12)/2 -> 1 | E12: 1 | F12: =(E12+G12)/2 -> 1 | G12: 1 | H12: =(G12+I12)/2 -> 1 | I12: 1 | J12: =(I12+K12)/2 -> 1.25 | K12: 1.5 | L12: =(K12+M12)/2 -> 1.75 | M12: 2 | N12: =(M12+O12)/2 -> 2.5 | O12: 3 | Q12: 6구간 | R12: ='환기량 산정'!B13 -> 0 | S12: =HLOOKUP(INT($R12),$B$6:$O$17,3)+(HLOOKUP(INT($R12)+1,$B$6:$O$17,3)-HLOOKUP(INT($R12),$B$6:$O$17,3))*($R12-INT($R12)) -> 0.5 | T12: =HLOOKUP(INT($R12),$B$6:$O$17,4)+(HLOOKUP(INT($R12)+1,$B$6:$O$17,4)-HLOOKUP(INT($R12),$B$6:$O$17,4))*($R12-INT($R12)) -> 1 | U12: =HLOOKUP(INT($R12),$B$6:$O$17,5)+(HLOOKUP(INT($R12)+1,$B$6:$O$17,5)-HLOOKUP(INT($R12),$B$6:$O$17,5))*($R12-INT($R12)) -> 1 | V12: =HLOOKUP(INT($R12),$B$6:$O$17,6)+(HLOOKUP(INT($R12)+1,$B$6:$O$17,6)-HLOOKUP(INT($R12),$B$6:$O$17,6))*($R12-INT($R12)) -> 1 | W12: =HLOOKUP(INT($R12),$B$6:$O$17,7)+(HLOOKUP(INT($R12)+1,$B$6:$O$17,7)-HLOOKUP(INT($R12),$B$6:$O$17,7))*($R12-INT($R12)) -> 1 | X12: =HLOOKUP(INT($R12),$B$6:$O$17,8)+(HLOOKUP(INT($R12)+1,$B$6:$O$17,8)-HLOOKUP(INT($R12),$B$6:$O$17,8))*($R12-INT($R12)) -> 1.5 | Y12: =HLOOKUP(INT($R12),$B$6:$O$17,9)+(HLOOKUP(INT($R12)+1,$B$6:$O$17,9)-HLOOKUP(INT($R12),$B$6:$O$17,9))*($R12-INT($R12)) -> 1.5 | Z12: =HLOOKUP(INT($R12),$B$6:$O$17,10)+(HLOOKUP(INT($R12)+1,$B$6:$O$17,10)-HLOOKUP(INT($R12),$B$6:$O$17,10))*($R12-INT($R12)) -> 2.5 | AB12: 6구간 | AC12: ='환기량 산정'!G13 -> 0 | AD12: =HLOOKUP(INT($AC12),$B$6:$O$17,3)+(HLOOKUP(INT($AC12)+1,$B$6:$O$17,3)-HLOOKUP(INT($AC12),$B$6:$O$17,3))*($AC12-INT($AC12)) -> 0.5 | AE12: =HLOOKUP(INT($AC12),$B$6:$O$17,4)+(HLOOKUP(INT($AC12)+1,$B$6:$O$17,4)-HLOOKUP(INT($AC12),$B$6:$O$17,4))*($AC12-INT($AC12)) -> 1 | AF12: =HLOOKUP(INT($AC12),$B$6:$O$17,5)+(HLOOKUP(INT($AC12)+1,$B$6:$O$17,5)-HLOOKUP(INT($AC12),$B$6:$O$17,5))*($AC12-INT($AC12)) -> 1 | AG12: =HLOOKUP(INT($AC12),$B$6:$O$17,6)+(HLOOKUP(INT($AC12)+1,$B$6:$O$17,6)-HLOOKUP(INT($AC12),$B$6:$O$17,6))*($AC12-INT($AC12)) -> 1 | AH12: =HLOOKUP(INT($AC12),$B$6:$O$17,7)+(HLOOKUP(INT($AC12)+1,$B$6:$O$17,7)-HLOOKUP(INT($AC12),$B$6:$O$17,7))*($AC12-INT($AC12)) -> 1 | AI12: =HLOOKUP(INT($AC12),$B$6:$O$17,8)+(HLOOKUP(INT($AC12)+1,$B$6:$O$17,8)-HLOOKUP(INT($AC12),$B$6:$O$17,8))*($AC12-INT($AC12)) -> 1.5 | AJ12: =HLOOKUP(INT($AC12),$B$6:$O$17,9)+(HLOOKUP(INT($AC12)+1,$B$6:$O$17,9)-HLOOKUP(INT($AC12),$B$6:$O$17,9))*($AC12-INT($AC12)) -> 1.5 | AK12: =HLOOKUP(INT($AC12),$B$6:$O$17,10)+(HLOOKUP(INT($AC12)+1,$B$6:$O$17,10)-HLOOKUP(INT($AC12),$B$6:$O$17,10))*($AC12-INT($AC12)) -> 2.5 | AM12: 참고조건2 | AN12: =AN10+1 -> 1 | AO12: =AO10+1 -> 1 | AP12: =AP10+1 -> 1 | AQ12: =AQ10+1 -> 1 | AR12: =AR10+1 -> 1 | AS12: =AS10+1 -> 1 | AT12: =AT10+1 -> 1 | AU12: =AU10+1 -> 1
A13: 60 | B13: =C13 -> 1 | C13: 1 | D13: =(C13+E13)/2 -> 1 | E13: 1 | F13: =(E13+G13)/2 -> 1 | G13: 1 | H13: =(G13+I13)/2 -> 1.25 | I13: 1.5 | J13: =(I13+K13)/2 -> 1.75 | K13: 2 | L13: =(K13+M13)/2 -> 2.5 | M13: 3 | N13: =(M13+O13)/2 -> 3.75 | O13: 4.5 | Q13: 7구간 | R13: ='환기량 산정'!C13 -> 0 | S13: =HLOOKUP(INT($R13),$B$6:$O$17,3)+(HLOOKUP(INT($R13)+1,$B$6:$O$17,3)-HLOOKUP(INT($R13),$B$6:$O$17,3))*($R13-INT($R13)) -> 0.5 | T13: =HLOOKUP(INT($R13),$B$6:$O$17,4)+(HLOOKUP(INT($R13)+1,$B$6:$O$17,4)-HLOOKUP(INT($R13),$B$6:$O$17,4))*($R13-INT($R13)) -> 1 | U13: =HLOOKUP(INT($R13),$B$6:$O$17,5)+(HLOOKUP(INT($R13)+1,$B$6:$O$17,5)-HLOOKUP(INT($R13),$B$6:$O$17,5))*($R13-INT($R13)) -> 1 | V13: =HLOOKUP(INT($R13),$B$6:$O$17,6)+(HLOOKUP(INT($R13)+1,$B$6:$O$17,6)-HLOOKUP(INT($R13),$B$6:$O$17,6))*($R13-INT($R13)) -> 1 | W13: =HLOOKUP(INT($R13),$B$6:$O$17,7)+(HLOOKUP(INT($R13)+1,$B$6:$O$17,7)-HLOOKUP(INT($R13),$B$6:$O$17,7))*($R13-INT($R13)) -> 1 | X13: =HLOOKUP(INT($R13),$B$6:$O$17,8)+(HLOOKUP(INT($R13)+1,$B$6:$O$17,8)-HLOOKUP(INT($R13),$B$6:$O$17,8))*($R13-INT($R13)) -> 1.5 | Y13: =HLOOKUP(INT($R13),$B$6:$O$17,9)+(HLOOKUP(INT($R13)+1,$B$6:$O$17,9)-HLOOKUP(INT($R13),$B$6:$O$17,9))*($R13-INT($R13)) -> 1.5 | Z13: =HLOOKUP(INT($R13),$B$6:$O$17,10)+(HLOOKUP(INT($R13)+1,$B$6:$O$17,10)-HLOOKUP(INT($R13),$B$6:$O$17,10))*($R13-INT($R13)) -> 2.5 | AB13: 7구간 | AC13: ='환기량 산정'!H13 -> 0 | AD13: =HLOOKUP(INT($AC13),$B$6:$O$17,3)+(HLOOKUP(INT($AC13)+1,$B$6:$O$17,3)-HLOOKUP(INT($AC13),$B$6:$O$17,3))*($AC13-INT($AC13)) -> 0.5 | AE13: =HLOOKUP(INT($AC13),$B$6:$O$17,4)+(HLOOKUP(INT($AC13)+1,$B$6:$O$17,4)-HLOOKUP(INT($AC13),$B$6:$O$17,4))*($AC13-INT($AC13)) -> 1 | AF13: =HLOOKUP(INT($AC13),$B$6:$O$17,5)+(HLOOKUP(INT($AC13)+1,$B$6:$O$17,5)-HLOOKUP(INT($AC13),$B$6:$O$17,5))*($AC13-INT($AC13)) -> 1 | AG13: =HLOOKUP(INT($AC13),$B$6:$O$17,6)+(HLOOKUP(INT($AC13)+1,$B$6:$O$17,6)-HLOOKUP(INT($AC13),$B$6:$O$17,6))*($AC13-INT($AC13)) -> 1 | AH13: =HLOOKUP(INT($AC13),$B$6:$O$17,7)+(HLOOKUP(INT($AC13)+1,$B$6:$O$17,7)-HLOOKUP(INT($AC13),$B$6:$O$17,7))*($AC13-INT($AC13)) -> 1 | AI13: =HLOOKUP(INT($AC13),$B$6:$O$17,8)+(HLOOKUP(INT($AC13)+1,$B$6:$O$17,8)-HLOOKUP(INT($AC13),$B$6:$O$17,8))*($AC13-INT($AC13)) -> 1.5 | AJ13: =HLOOKUP(INT($AC13),$B$6:$O$17,9)+(HLOOKUP(INT($AC13)+1,$B$6:$O$17,9)-HLOOKUP(INT($AC13),$B$6:$O$17,9))*($AC13-INT($AC13)) -> 1.5 | AK13: =HLOOKUP(INT($AC13),$B$6:$O$17,10)+(HLOOKUP(INT($AC13)+1,$B$6:$O$17,10)-HLOOKUP(INT($AC13),$B$6:$O$17,10))*($AC13-INT($AC13)) -> 2.5 | AM13: 참고값2 | AN13: =HLOOKUP(AN12,$B$6:$O$17,AN14) -> 0.75 | AO13: =HLOOKUP(AO12,$B$6:$O$17,AO14) -> 1 | AP13: =HLOOKUP(AP12,$B$6:$O$17,AP14) -> 1 | AQ13: =HLOOKUP(AQ12,$B$6:$O$17,AQ14) -> 1.25 | AR13: =HLOOKUP(AR12,$B$6:$O$17,AR14) -> 1.25 | AS13: =HLOOKUP(AS12,$B$6:$O$17,AS14) -> 1.75 | AT13: =HLOOKUP(AT12,$B$6:$O$17,AT14) -> 2 | AU13: =HLOOKUP(AU12,$B$6:$O$17,AU14) -> 3.25
A14: 70 | B14: =C14 -> 1 | C14: 1 | D14: =(C14+E14)/2 -> 1 | E14: 1 | F14: =(E14+G14)/2 -> 1.25 | G14: 1.5 | H14: =(G14+I14)/2 -> 1.5 | I14: 1.5 | J14: =(I14+K14)/2 -> 2 | K14: 2.5 | L14: =(K14+M14)/2 -> 3.5 | M14: 4.5 | N14: =(M14+O14)/2 -> 6 | O14: 7.5 | Q14: 8구간 | R14: ='환기량 산정'!D13 -> 0 | S14: =HLOOKUP(INT($R14),$B$6:$O$17,3)+(HLOOKUP(INT($R14)+1,$B$6:$O$17,3)-HLOOKUP(INT($R14),$B$6:$O$17,3))*($R14-INT($R14)) -> 0.5 | T14: =HLOOKUP(INT($R14),$B$6:$O$17,4)+(HLOOKUP(INT($R14)+1,$B$6:$O$17,4)-HLOOKUP(INT($R14),$B$6:$O$17,4))*($R14-INT($R14)) -> 1 | U14: =HLOOKUP(INT($R14),$B$6:$O$17,5)+(HLOOKUP(INT($R14)+1,$B$6:$O$17,5)-HLOOKUP(INT($R14),$B$6:$O$17,5))*($R14-INT($R14)) -> 1 | V14: =HLOOKUP(INT($R14),$B$6:$O$17,6)+(HLOOKUP(INT($R14)+1,$B$6:$O$17,6)-HLOOKUP(INT($R14),$B$6:$O$17,6))*($R14-INT($R14)) -> 1 | W14: =HLOOKUP(INT($R14),$B$6:$O$17,7)+(HLOOKUP(INT($R14)+1,$B$6:$O$17,7)-HLOOKUP(INT($R14),$B$6:$O$17,7))*($R14-INT($R14)) -> 1 | X14: =HLOOKUP(INT($R14),$B$6:$O$17,8)+(HLOOKUP(INT($R14)+1,$B$6:$O$17,8)-HLOOKUP(INT($R14),$B$6:$O$17,8))*($R14-INT($R14)) -> 1.5 | Y14: =HLOOKUP(INT($R14),$B$6:$O$17,9)+(HLOOKUP(INT($R14)+1,$B$6:$O$17,9)-HLOOKUP(INT($R14),$B$6:$O$17,9))*($R14-INT($R14)) -> 1.5 | Z14: =HLOOKUP(INT($R14),$B$6:$O$17,10)+(HLOOKUP(INT($R14)+1,$B$6:$O$17,10)-HLOOKUP(INT($R14),$B$6:$O$17,10))*($R14-INT($R14)) -> 2.5 | AB14: 8구간 | AC14: ='환기량 산정'!I13 -> 0 | AD14: =HLOOKUP(INT($AC14),$B$6:$O$17,3)+(HLOOKUP(INT($AC14)+1,$B$6:$O$17,3)-HLOOKUP(INT($AC14),$B$6:$O$17,3))*($AC14-INT($AC14)) -> 0.5 | AE14: =HLOOKUP(INT($AC14),$B$6:$O$17,4)+(HLOOKUP(INT($AC14)+1,$B$6:$O$17,4)-HLOOKUP(INT($AC14),$B$6:$O$17,4))*($AC14-INT($AC14)) -> 1 | AF14: =HLOOKUP(INT($AC14),$B$6:$O$17,5)+(HLOOKUP(INT($AC14)+1,$B$6:$O$17,5)-HLOOKUP(INT($AC14),$B$6:$O$17,5))*($AC14-INT($AC14)) -> 1 | AG14: =HLOOKUP(INT($AC14),$B$6:$O$17,6)+(HLOOKUP(INT($AC14)+1,$B$6:$O$17,6)-HLOOKUP(INT($AC14),$B$6:$O$17,6))*($AC14-INT($AC14)) -> 1 | AH14: =HLOOKUP(INT($AC14),$B$6:$O$17,7)+(HLOOKUP(INT($AC14)+1,$B$6:$O$17,7)-HLOOKUP(INT($AC14),$B$6:$O$17,7))*($AC14-INT($AC14)) -> 1 | AI14: =HLOOKUP(INT($AC14),$B$6:$O$17,8)+(HLOOKUP(INT($AC14)+1,$B$6:$O$17,8)-HLOOKUP(INT($AC14),$B$6:$O$17,8))*($AC14-INT($AC14)) -> 1.5 | AJ14: =HLOOKUP(INT($AC14),$B$6:$O$17,9)+(HLOOKUP(INT($AC14)+1,$B$6:$O$17,9)-HLOOKUP(INT($AC14),$B$6:$O$17,9))*($AC14-INT($AC14)) -> 1.5 | AK14: =HLOOKUP(INT($AC14),$B$6:$O$17,10)+(HLOOKUP(INT($AC14)+1,$B$6:$O$17,10)-HLOOKUP(INT($AC14),$B$6:$O$17,10))*($AC14-INT($AC14)) -> 2.5 | AN14: 3 | AO14: 4 | AP14: 5 | AQ14: 6 | AR14: 7 | AS14: 8 | AT14: 9 | AU14: 10
A15: 80 | B15: =C15 -> 1 | C15: 1 | D15: =(C15+E15)/2 -> 1.25 | E15: 1.5 | F15: =(E15+G15)/2 -> 1.5 | G15: 1.5 | H15: =(G15+I15)/2 -> 2 | I15: 2.5 | J15: =(I15+K15)/2 -> 3.25 | K15: 4 | L15: =(K15+M15)/2 -> 5.25 | M15: 6.5 | N15: =(M15+O15)/2 -> 9.25 | O15: 12 | Q15: 9구간 | R15: ='환기량 산정'!E13 -> 0 | S15: =HLOOKUP(INT($R15),$B$6:$O$17,3)+(HLOOKUP(INT($R15)+1,$B$6:$O$17,3)-HLOOKUP(INT($R15),$B$6:$O$17,3))*($R15-INT($R15)) -> 0.5 | T15: =HLOOKUP(INT($R15),$B$6:$O$17,4)+(HLOOKUP(INT($R15)+1,$B$6:$O$17,4)-HLOOKUP(INT($R15),$B$6:$O$17,4))*($R15-INT($R15)) -> 1 | U15: =HLOOKUP(INT($R15),$B$6:$O$17,5)+(HLOOKUP(INT($R15)+1,$B$6:$O$17,5)-HLOOKUP(INT($R15),$B$6:$O$17,5))*($R15-INT($R15)) -> 1 | V15: =HLOOKUP(INT($R15),$B$6:$O$17,6)+(HLOOKUP(INT($R15)+1,$B$6:$O$17,6)-HLOOKUP(INT($R15),$B$6:$O$17,6))*($R15-INT($R15)) -> 1 | W15: =HLOOKUP(INT($R15),$B$6:$O$17,7)+(HLOOKUP(INT($R15)+1,$B$6:$O$17,7)-HLOOKUP(INT($R15),$B$6:$O$17,7))*($R15-INT($R15)) -> 1 | X15: =HLOOKUP(INT($R15),$B$6:$O$17,8)+(HLOOKUP(INT($R15)+1,$B$6:$O$17,8)-HLOOKUP(INT($R15),$B$6:$O$17,8))*($R15-INT($R15)) -> 1.5 | Y15: =HLOOKUP(INT($R15),$B$6:$O$17,9)+(HLOOKUP(INT($R15)+1,$B$6:$O$17,9)-HLOOKUP(INT($R15),$B$6:$O$17,9))*($R15-INT($R15)) -> 1.5 | Z15: =HLOOKUP(INT($R15),$B$6:$O$17,10)+(HLOOKUP(INT($R15)+1,$B$6:$O$17,10)-HLOOKUP(INT($R15),$B$6:$O$17,10))*($R15-INT($R15)) -> 2.5 | AB15: 9구간 | AC15: ='환기량 산정'!J13 -> 0 | AD15: =HLOOKUP(INT($AC15),$B$6:$O$17,3)+(HLOOKUP(INT($AC15)+1,$B$6:$O$17,3)-HLOOKUP(INT($AC15),$B$6:$O$17,3))*($AC15-INT($AC15)) -> 0.5 | AE15: =HLOOKUP(INT($AC15),$B$6:$O$17,4)+(HLOOKUP(INT($AC15)+1,$B$6:$O$17,4)-HLOOKUP(INT($AC15),$B$6:$O$17,4))*($AC15-INT($AC15)) -> 1 | AF15: =HLOOKUP(INT($AC15),$B$6:$O$17,5)+(HLOOKUP(INT($AC15)+1,$B$6:$O$17,5)-HLOOKUP(INT($AC15),$B$6:$O$17,5))*($AC15-INT($AC15)) -> 1 | AG15: =HLOOKUP(INT($AC15),$B$6:$O$17,6)+(HLOOKUP(INT($AC15)+1,$B$6:$O$17,6)-HLOOKUP(INT($AC15),$B$6:$O$17,6))*($AC15-INT($AC15)) -> 1 | AH15: =HLOOKUP(INT($AC15),$B$6:$O$17,7)+(HLOOKUP(INT($AC15)+1,$B$6:$O$17,7)-HLOOKUP(INT($AC15),$B$6:$O$17,7))*($AC15-INT($AC15)) -> 1 | AI15: =HLOOKUP(INT($AC15),$B$6:$O$17,8)+(HLOOKUP(INT($AC15)+1,$B$6:$O$17,8)-HLOOKUP(INT($AC15),$B$6:$O$17,8))*($AC15-INT($AC15)) -> 1.5 | AJ15: =HLOOKUP(INT($AC15),$B$6:$O$17,9)+(HLOOKUP(INT($AC15)+1,$B$6:$O$17,9)-HLOOKUP(INT($AC15),$B$6:$O$17,9))*($AC15-INT($AC15)) -> 1.5 | AK15: =HLOOKUP(INT($AC15),$B$6:$O$17,10)+(HLOOKUP(INT($AC15)+1,$B$6:$O$17,10)-HLOOKUP(INT($AC15),$B$6:$O$17,10))*($AC15-INT($AC15)) -> 2.5
A16: 90 | B16: =C16 -> 1.5 | C16: 1.5 | D16: =(C16+E16)/2 -> 1.5 | E16: 1.5 | F16: =(E16+G16)/2 -> 1.5 | G16: 1.5 | H16: =(G16+I16)/2 -> 2.25 | I16: 3 | J16: =(I16+K16)/2 -> 4.5 | K16: 6 | L16: =(K16+M16)/2 -> 8.25 | M16: 10.5 | N16: =(M16+O16)/2 -> 14.75 | O16: 19 | Q16: 10구간 | R16: ='환기량 산정'!F13 -> 0 | S16: =HLOOKUP(INT($R16),$B$6:$O$17,3)+(HLOOKUP(INT($R16)+1,$B$6:$O$17,3)-HLOOKUP(INT($R16),$B$6:$O$17,3))*($R16-INT($R16)) -> 0.5 | T16: =HLOOKUP(INT($R16),$B$6:$O$17,4)+(HLOOKUP(INT($R16)+1,$B$6:$O$17,4)-HLOOKUP(INT($R16),$B$6:$O$17,4))*($R16-INT($R16)) -> 1 | U16: =HLOOKUP(INT($R16),$B$6:$O$17,5)+(HLOOKUP(INT($R16)+1,$B$6:$O$17,5)-HLOOKUP(INT($R16),$B$6:$O$17,5))*($R16-INT($R16)) -> 1 | V16: =HLOOKUP(INT($R16),$B$6:$O$17,6)+(HLOOKUP(INT($R16)+1,$B$6:$O$17,6)-HLOOKUP(INT($R16),$B$6:$O$17,6))*($R16-INT($R16)) -> 1 | W16: =HLOOKUP(INT($R16),$B$6:$O$17,7)+(HLOOKUP(INT($R16)+1,$B$6:$O$17,7)-HLOOKUP(INT($R16),$B$6:$O$17,7))*($R16-INT($R16)) -> 1 | X16: =HLOOKUP(INT($R16),$B$6:$O$17,8)+(HLOOKUP(INT($R16)+1,$B$6:$O$17,8)-HLOOKUP(INT($R16),$B$6:$O$17,8))*($R16-INT($R16)) -> 1.5 | Y16: =HLOOKUP(INT($R16),$B$6:$O$17,9)+(HLOOKUP(INT($R16)+1,$B$6:$O$17,9)-HLOOKUP(INT($R16),$B$6:$O$17,9))*($R16-INT($R16)) -> 1.5 | Z16: =HLOOKUP(INT($R16),$B$6:$O$17,10)+(HLOOKUP(INT($R16)+1,$B$6:$O$17,10)-HLOOKUP(INT($R16),$B$6:$O$17,10))*($R16-INT($R16)) -> 2.5 | AB16: 10구간 | AC16: ='환기량 산정'!K13 -> 0 | AD16: =HLOOKUP(INT($AC16),$B$6:$O$17,3)+(HLOOKUP(INT($AC16)+1,$B$6:$O$17,3)-HLOOKUP(INT($AC16),$B$6:$O$17,3))*($AC16-INT($AC16)) -> 0.5 | AE16: =HLOOKUP(INT($AC16),$B$6:$O$17,4)+(HLOOKUP(INT($AC16)+1,$B$6:$O$17,4)-HLOOKUP(INT($AC16),$B$6:$O$17,4))*($AC16-INT($AC16)) -> 1 | AF16: =HLOOKUP(INT($AC16),$B$6:$O$17,5)+(HLOOKUP(INT($AC16)+1,$B$6:$O$17,5)-HLOOKUP(INT($AC16),$B$6:$O$17,5))*($AC16-INT($AC16)) -> 1 | AG16: =HLOOKUP(INT($AC16),$B$6:$O$17,6)+(HLOOKUP(INT($AC16)+1,$B$6:$O$17,6)-HLOOKUP(INT($AC16),$B$6:$O$17,6))*($AC16-INT($AC16)) -> 1 | AH16: =HLOOKUP(INT($AC16),$B$6:$O$17,7)+(HLOOKUP(INT($AC16)+1,$B$6:$O$17,7)-HLOOKUP(INT($AC16),$B$6:$O$17,7))*($AC16-INT($AC16)) -> 1 | AI16: =HLOOKUP(INT($AC16),$B$6:$O$17,8)+(HLOOKUP(INT($AC16)+1,$B$6:$O$17,8)-HLOOKUP(INT($AC16),$B$6:$O$17,8))*($AC16-INT($AC16)) -> 1.5 | AJ16: =HLOOKUP(INT($AC16),$B$6:$O$17,9)+(HLOOKUP(INT($AC16)+1,$B$6:$O$17,9)-HLOOKUP(INT($AC16),$B$6:$O$17,9))*($AC16-INT($AC16)) -> 1.5 | AK16: =HLOOKUP(INT($AC16),$B$6:$O$17,10)+(HLOOKUP(INT($AC16)+1,$B$6:$O$17,10)-HLOOKUP(INT($AC16),$B$6:$O$17,10))*($AC16-INT($AC16)) -> 2.5
A17: 100 | B17: =C17 -> 2.5 | C17: 2.5 | D17: =(C17+E17)/2 -> 2 | E17: 1.5 | F17: =(E17+G17)/2 -> 1.75 | G17: 2 | H17: =(G17+I17)/2 -> 2.75 | I17: 3.5 | J17: =(I17+K17)/2 -> 5.5 | K17: 7.5 | L17: =(K17+M17)/2 -> 11 | M17: 14.5 | N17: =(M17+O17)/2 -> 19.5 | O17: 24.5
A18: (2) 승용차 / 경유
C19: 경사도(%) | Q19: (1.1-2) 승용차 / 경유 | AB19: (1.2-2) 승용차 / 경유 | AM19: 검증
A20: 차속 | B20: -100 | C20: -6 | D20: =(C20+E20)/2 -> -5 | E20: -4 | F20: =(E20+G20)/2 -> -3 | G20: -2 | H20: =(G20+I20)/2 -> -1 | I20: 0 | J20: =(I20+K20)/2 -> 1 | K20: 2 | L20: =(K20+M20)/2 -> 3 | M20: 4 | N20: =(M20+O20)/2 -> 5 | O20: 6 | Q20: 구간 | R20: 경사도(%) | S20: 10 | T20: 20 | U20: 30 | V20: 40 | W20: 50 | X20: 60 | Y20: 70 | Z20: 80 | AB20: 구간 | AC20: 경사도(%) | AD20: 10 | AE20: 20 | AF20: 30 | AG20: 40 | AH20: 50 | AI20: 60 | AJ20: 70 | AK20: 80 | AM20: 구분 | AN20: 10 | AO20: 20 | AP20: 30 | AQ20: 40 | AR20: 50 | AS20: 60 | AT20: 70 | AU20: 80
A21: 0 | B21: =C21 -> 0.174 | C21: 0.174 | D21: =(C21+E21)/2 -> 0.174 | E21: 0.174 | F21: =(E21+G21)/2 -> 0.174 | G21: 0.174 | H21: =(G21+I21)/2 -> 0.174 | I21: 0.174 | J21: =(I21+K21)/2 -> 0.174 | K21: 0.174 | L21: =(K21+M21)/2 -> 0.174 | M21: 0.174 | N21: =(M21+O21)/2 -> 0.174 | O21: 0.174 | Q21: 1구간 | R21: =R7 -> 0 | S21: =HLOOKUP(INT($R21),$B$20:$O$31,3)+(HLOOKUP(INT($R21)+1,$B$20:$O$31,3)-HLOOKUP(INT($R21),$B$20:$O$31,3))*($R21-INT($R21)) -> 0.652 | T21: =HLOOKUP(INT($R21),$B$20:$O$31,4)+(HLOOKUP(INT($R21)+1,$B$20:$O$31,4)-HLOOKUP(INT($R21),$B$20:$O$31,4))*($R21-INT($R21)) -> 0.783 | U21: =HLOOKUP(INT($R21),$B$20:$O$31,5)+(HLOOKUP(INT($R21)+1,$B$20:$O$31,5)-HLOOKUP(INT($R21),$B$20:$O$31,5))*($R21-INT($R21)) -> 0.87 | V21: =HLOOKUP(INT($R21),$B$20:$O$31,6)+(HLOOKUP(INT($R21)+1,$B$20:$O$31,6)-HLOOKUP(INT($R21),$B$20:$O$31,6))*($R21-INT($R21)) -> 1 | W21: =HLOOKUP(INT($R21),$B$20:$O$31,7)+(HLOOKUP(INT($R21)+1,$B$20:$O$31,7)-HLOOKUP(INT($R21),$B$20:$O$31,7))*($R21-INT($R21)) -> 1.174 | X21: =HLOOKUP(INT($R21),$B$20:$O$31,8)+(HLOOKUP(INT($R21)+1,$B$20:$O$31,8)-HLOOKUP(INT($R21),$B$20:$O$31,8))*($R21-INT($R21)) -> 1.217 | Y21: =HLOOKUP(INT($R21),$B$20:$O$31,9)+(HLOOKUP(INT($R21)+1,$B$20:$O$31,9)-HLOOKUP(INT($R21),$B$20:$O$31,9))*($R21-INT($R21)) -> 1.391 | Z21: =HLOOKUP(INT($R21),$B$20:$O$31,10)+(HLOOKUP(INT($R21)+1,$B$20:$O$31,10)-HLOOKUP(INT($R21),$B$20:$O$31,10))*($R21-INT($R21)) -> 1.652 | AB21: 1구간 | AC21: =AC7 -> 1.784 | AD21: =HLOOKUP(INT($AC21),$B$20:$O$31,3)+(HLOOKUP(INT($AC21)+1,$B$20:$O$31,3)-HLOOKUP(INT($AC21),$B$20:$O$31,3))*($AC21-INT($AC21)) -> 0.691248 | AE21: =HLOOKUP(INT($AC21),$B$20:$O$31,4)+(HLOOKUP(INT($AC21)+1,$B$20:$O$31,4)-HLOOKUP(INT($AC21),$B$20:$O$31,4))*($AC21-INT($AC21)) -> 0.860604 | AF21: =HLOOKUP(INT($AC21),$B$20:$O$31,5)+(HLOOKUP(INT($AC21)+1,$B$20:$O$31,5)-HLOOKUP(INT($AC21),$B$20:$O$31,5))*($AC21-INT($AC21)) -> 0.98596 | AG21: =HLOOKUP(INT($AC21),$B$20:$O$31,6)+(HLOOKUP(INT($AC21)+1,$B$20:$O$31,6)-HLOOKUP(INT($AC21),$B$20:$O$31,6))*($AC21-INT($AC21)) -> 1.193564 | AH21: =HLOOKUP(INT($AC21),$B$20:$O$31,7)+(HLOOKUP(INT($AC21)+1,$B$20:$O$31,7)-HLOOKUP(INT($AC21),$B$20:$O$31,7))*($AC21-INT($AC21)) -> 1.445168 | AI21: =HLOOKUP(INT($AC21),$B$20:$O$31,8)+(HLOOKUP(INT($AC21)+1,$B$20:$O$31,8)-HLOOKUP(INT($AC21),$B$20:$O$31,8))*($AC21-INT($AC21)) -> 1.60502 | AJ21: =HLOOKUP(INT($AC21),$B$20:$O$31,9)+(HLOOKUP(INT($AC21)+1,$B$20:$O$31,9)-HLOOKUP(INT($AC21),$B$20:$O$31,9))*($AC21-INT($AC21)) -> 1.818268 | AK21: =HLOOKUP(INT($AC21),$B$20:$O$31,10)+(HLOOKUP(INT($AC21)+1,$B$20:$O$31,10)-HLOOKUP(INT($AC21),$B$20:$O$31,10))*($AC21-INT($AC21)) -> 2.233584 | AM21: 경사도(%) | AN21: =R30 -> 0 | AO21: =AN21 -> 0 | AP21: =AO21 -> 0 | AQ21: =AP21 -> 0 | AR21: =AQ21 -> 0 | AS21: =AR21 -> 0 | AT21: =AS21 -> 0 | AU21: =AT21 -> 0
A22: 10 | B22: =C22 -> 0.478 | C22: 0.478 | D22: =(C22+E22)/2 -> 0.5 | E22: 0.522 | F22: =(E22+G22)/2 -> 0.5435 | G22: 0.565 | H22: =(G22+I22)/2 -> 0.6085 | I22: 0.652 | J22: =(I22+K22)/2 -> 0.674 | K22: 0.696 | L22: =(K22+M22)/2 -> 0.7395 | M22: 0.783 | N22: =(M22+O22)/2 -> 0.8265 | O22: 0.87 | Q22: 2구간 | R22: =R8 -> 0 | S22: =HLOOKUP(INT($R22),$B$20:$O$31,3)+(HLOOKUP(INT($R22)+1,$B$20:$O$31,3)-HLOOKUP(INT($R22),$B$20:$O$31,3))*($R22-INT($R22)) -> 0.652 | T22: =HLOOKUP(INT($R22),$B$20:$O$31,4)+(HLOOKUP(INT($R22)+1,$B$20:$O$31,4)-HLOOKUP(INT($R22),$B$20:$O$31,4))*($R22-INT($R22)) -> 0.783 | U22: =HLOOKUP(INT($R22),$B$20:$O$31,5)+(HLOOKUP(INT($R22)+1,$B$20:$O$31,5)-HLOOKUP(INT($R22),$B$20:$O$31,5))*($R22-INT($R22)) -> 0.87 | V22: =HLOOKUP(INT($R22),$B$20:$O$31,6)+(HLOOKUP(INT($R22)+1,$B$20:$O$31,6)-HLOOKUP(INT($R22),$B$20:$O$31,6))*($R22-INT($R22)) -> 1 | W22: =HLOOKUP(INT($R22),$B$20:$O$31,7)+(HLOOKUP(INT($R22)+1,$B$20:$O$31,7)-HLOOKUP(INT($R22),$B$20:$O$31,7))*($R22-INT($R22)) -> 1.174 | X22: =HLOOKUP(INT($R22),$B$20:$O$31,8)+(HLOOKUP(INT($R22)+1,$B$20:$O$31,8)-HLOOKUP(INT($R22),$B$20:$O$31,8))*($R22-INT($R22)) -> 1.217 | Y22: =HLOOKUP(INT($R22),$B$20:$O$31,9)+(HLOOKUP(INT($R22)+1,$B$20:$O$31,9)-HLOOKUP(INT($R22),$B$20:$O$31,9))*($R22-INT($R22)) -> 1.391 | Z22: =HLOOKUP(INT($R22),$B$20:$O$31,10)+(HLOOKUP(INT($R22)+1,$B$20:$O$31,10)-HLOOKUP(INT($R22),$B$20:$O$31,10))*($R22-INT($R22)) -> 1.652 | AB22: 2구간 | AC22: =AC8 -> 0 | AD22: =HLOOKUP(INT($AC22),$B$20:$O$31,3)+(HLOOKUP(INT($AC22)+1,$B$20:$O$31,3)-HLOOKUP(INT($AC22),$B$20:$O$31,3))*($AC22-INT($AC22)) -> 0.652 | AE22: =HLOOKUP(INT($AC22),$B$20:$O$31,4)+(HLOOKUP(INT($AC22)+1,$B$20:$O$31,4)-HLOOKUP(INT($AC22),$B$20:$O$31,4))*($AC22-INT($AC22)) -> 0.783 | AF22: =HLOOKUP(INT($AC22),$B$20:$O$31,5)+(HLOOKUP(INT($AC22)+1,$B$20:$O$31,5)-HLOOKUP(INT($AC22),$B$20:$O$31,5))*($AC22-INT($AC22)) -> 0.87 | AG22: =HLOOKUP(INT($AC22),$B$20:$O$31,6)+(HLOOKUP(INT($AC22)+1,$B$20:$O$31,6)-HLOOKUP(INT($AC22),$B$20:$O$31,6))*($AC22-INT($AC22)) -> 1 | AH22: =HLOOKUP(INT($AC22),$B$20:$O$31,7)+(HLOOKUP(INT($AC22)+1,$B$20:$O$31,7)-HLOOKUP(INT($AC22),$B$20:$O$31,7))*($AC22-INT($AC22)) -> 1.174 | AI22: =HLOOKUP(INT($AC22),$B$20:$O$31,8)+(HLOOKUP(INT($AC22)+1,$B$20:$O$31,8)-HLOOKUP(INT($AC22),$B$20:$O$31,8))*($AC22-INT($AC22)) -> 1.217 | AJ22: =HLOOKUP(INT($AC22),$B$20:$O$31,9)+(HLOOKUP(INT($AC22)+1,$B$20:$O$31,9)-HLOOKUP(INT($AC22),$B$20:$O$31,9))*($AC22-INT($AC22)) -> 1.391 | AK22: =HLOOKUP(INT($AC22),$B$20:$O$31,10)+(HLOOKUP(INT($AC22)+1,$B$20:$O$31,10)-HLOOKUP(INT($AC22),$B$20:$O$31,10))*($AC22-INT($AC22)) -> 1.652 | AM22: 보정계수 | AN22: =AN25+(AN27-AN25)*(AN21-AN24) -> 0.652 | AO22: =AO25+(AO27-AO25)*(AO21-AO24) -> 0.783 | AP22: =AP25+(AP27-AP25)*(AP21-AP24) -> 0.87 | AQ22: =AQ25+(AQ27-AQ25)*(AQ21-AQ24) -> 1 | AR22: =AR25+(AR27-AR25)*(AR21-AR24) -> 1.174 | AS22: =AS25+(AS27-AS25)*(AS21-AS24) -> 1.217 | AT22: =AT25+(AT27-AT25)*(AT21-AT24) -> 1.391 | AU22: =AU25+(AU27-AU25)*(AU21-AU24) -> 1.652
A23: 20 | B23: =C23 -> 0.478 | C23: 0.478 | D23: =(C23+E23)/2 -> 0.5215 | E23: 0.565 | F23: =(E23+G23)/2 -> 0.6085 | G23: 0.652 | H23: =(G23+I23)/2 -> 0.7175 | I23: 0.783 | J23: =(I23+K23)/2 -> 0.8265 | K23: 0.87 | L23: =(K23+M23)/2 -> 0.935 | M23: 1 | N23: =(M23+O23)/2 -> 1.087 | O23: 1.174 | Q23: 3구간 | R23: =R9 -> 0 | S23: =HLOOKUP(INT($R23),$B$20:$O$31,3)+(HLOOKUP(INT($R23)+1,$B$20:$O$31,3)-HLOOKUP(INT($R23),$B$20:$O$31,3))*($R23-INT($R23)) -> 0.652 | T23: =HLOOKUP(INT($R23),$B$20:$O$31,4)+(HLOOKUP(INT($R23)+1,$B$20:$O$31,4)-HLOOKUP(INT($R23),$B$20:$O$31,4))*($R23-INT($R23)) -> 0.783 | U23: =HLOOKUP(INT($R23),$B$20:$O$31,5)+(HLOOKUP(INT($R23)+1,$B$20:$O$31,5)-HLOOKUP(INT($R23),$B$20:$O$31,5))*($R23-INT($R23)) -> 0.87 | V23: =HLOOKUP(INT($R23),$B$20:$O$31,6)+(HLOOKUP(INT($R23)+1,$B$20:$O$31,6)-HLOOKUP(INT($R23),$B$20:$O$31,6))*($R23-INT($R23)) -> 1 | W23: =HLOOKUP(INT($R23),$B$20:$O$31,7)+(HLOOKUP(INT($R23)+1,$B$20:$O$31,7)-HLOOKUP(INT($R23),$B$20:$O$31,7))*($R23-INT($R23)) -> 1.174 | X23: =HLOOKUP(INT($R23),$B$20:$O$31,8)+(HLOOKUP(INT($R23)+1,$B$20:$O$31,8)-HLOOKUP(INT($R23),$B$20:$O$31,8))*($R23-INT($R23)) -> 1.217 | Y23: =HLOOKUP(INT($R23),$B$20:$O$31,9)+(HLOOKUP(INT($R23)+1,$B$20:$O$31,9)-HLOOKUP(INT($R23),$B$20:$O$31,9))*($R23-INT($R23)) -> 1.391 | Z23: =HLOOKUP(INT($R23),$B$20:$O$31,10)+(HLOOKUP(INT($R23)+1,$B$20:$O$31,10)-HLOOKUP(INT($R23),$B$20:$O$31,10))*($R23-INT($R23)) -> 1.652 | AB23: 3구간 | AC23: =AC9 -> 0 | AD23: =HLOOKUP(INT($AC23),$B$20:$O$31,3)+(HLOOKUP(INT($AC23)+1,$B$20:$O$31,3)-HLOOKUP(INT($AC23),$B$20:$O$31,3))*($AC23-INT($AC23)) -> 0.652 | AE23: =HLOOKUP(INT($AC23),$B$20:$O$31,4)+(HLOOKUP(INT($AC23)+1,$B$20:$O$31,4)-HLOOKUP(INT($AC23),$B$20:$O$31,4))*($AC23-INT($AC23)) -> 0.783 | AF23: =HLOOKUP(INT($AC23),$B$20:$O$31,5)+(HLOOKUP(INT($AC23)+1,$B$20:$O$31,5)-HLOOKUP(INT($AC23),$B$20:$O$31,5))*($AC23-INT($AC23)) -> 0.87 | AG23: =HLOOKUP(INT($AC23),$B$20:$O$31,6)+(HLOOKUP(INT($AC23)+1,$B$20:$O$31,6)-HLOOKUP(INT($AC23),$B$20:$O$31,6))*($AC23-INT($AC23)) -> 1 | AH23: =HLOOKUP(INT($AC23),$B$20:$O$31,7)+(HLOOKUP(INT($AC23)+1,$B$20:$O$31,7)-HLOOKUP(INT($AC23),$B$20:$O$31,7))*($AC23-INT($AC23)) -> 1.174 | AI23: =HLOOKUP(INT($AC23),$B$20:$O$31,8)+(HLOOKUP(INT($AC23)+1,$B$20:$O$31,8)-HLOOKUP(INT($AC23),$B$20:$O$31,8))*($AC23-INT($AC23)) -> 1.217 | AJ23: =HLOOKUP(INT($AC23),$B$20:$O$31,9)+(HLOOKUP(INT($AC23)+1,$B$20:$O$31,9)-HLOOKUP(INT($AC23),$B$20:$O$31,9))*($AC23-INT($AC23)) -> 1.391 | AK23: =HLOOKUP(INT($AC23),$B$20:$O$31,10)+(HLOOKUP(INT($AC23)+1,$B$20:$O$31,10)-HLOOKUP(INT($AC23),$B$20:$O$31,10))*($AC23-INT($AC23)) -> 1.652
A24: 30 | B24: =C24 -> 0.478 | C24: 0.478 | D24: =(C24+E24)/2 -> 0.5435 | E24: 0.609 | F24: =(E24+G24)/2 -> 0.6525 | G24: 0.696 | H24: =(G24+I24)/2 -> 0.783 | I24: 0.87 | J24: =(I24+K24)/2 -> 0.935 | K24: 1 | L24: =(K24+M24)/2 -> 1.087 | M24: 1.174 | N24: =(M24+O24)/2 -> 1.261 | O24: 1.348 | Q24: 4구간 | R24: =R10 -> 0 | S24: =HLOOKUP(INT($R24),$B$20:$O$31,3)+(HLOOKUP(INT($R24)+1,$B$20:$O$31,3)-HLOOKUP(INT($R24),$B$20:$O$31,3))*($R24-INT($R24)) -> 0.652 | T24: =HLOOKUP(INT($R24),$B$20:$O$31,4)+(HLOOKUP(INT($R24)+1,$B$20:$O$31,4)-HLOOKUP(INT($R24),$B$20:$O$31,4))*($R24-INT($R24)) -> 0.783 | U24: =HLOOKUP(INT($R24),$B$20:$O$31,5)+(HLOOKUP(INT($R24)+1,$B$20:$O$31,5)-HLOOKUP(INT($R24),$B$20:$O$31,5))*($R24-INT($R24)) -> 0.87 | V24: =HLOOKUP(INT($R24),$B$20:$O$31,6)+(HLOOKUP(INT($R24)+1,$B$20:$O$31,6)-HLOOKUP(INT($R24),$B$20:$O$31,6))*($R24-INT($R24)) -> 1 | W24: =HLOOKUP(INT($R24),$B$20:$O$31,7)+(HLOOKUP(INT($R24)+1,$B$20:$O$31,7)-HLOOKUP(INT($R24),$B$20:$O$31,7))*($R24-INT($R24)) -> 1.174 | X24: =HLOOKUP(INT($R24),$B$20:$O$31,8)+(HLOOKUP(INT($R24)+1,$B$20:$O$31,8)-HLOOKUP(INT($R24),$B$20:$O$31,8))*($R24-INT($R24)) -> 1.217 | Y24: =HLOOKUP(INT($R24),$B$20:$O$31,9)+(HLOOKUP(INT($R24)+1,$B$20:$O$31,9)-HLOOKUP(INT($R24),$B$20:$O$31,9))*($R24-INT($R24)) -> 1.391 | Z24: =HLOOKUP(INT($R24),$B$20:$O$31,10)+(HLOOKUP(INT($R24)+1,$B$20:$O$31,10)-HLOOKUP(INT($R24),$B$20:$O$31,10))*($R24-INT($R24)) -> 1.652 | AB24: 4구간 | AC24: =AC10 -> 0 | AD24: =HLOOKUP(INT($AC24),$B$20:$O$31,3)+(HLOOKUP(INT($AC24)+1,$B$20:$O$31,3)-HLOOKUP(INT($AC24),$B$20:$O$31,3))*($AC24-INT($AC24)) -> 0.652 | AE24: =HLOOKUP(INT($AC24),$B$20:$O$31,4)+(HLOOKUP(INT($AC24)+1,$B$20:$O$31,4)-HLOOKUP(INT($AC24),$B$20:$O$31,4))*($AC24-INT($AC24)) -> 0.783 | AF24: =HLOOKUP(INT($AC24),$B$20:$O$31,5)+(HLOOKUP(INT($AC24)+1,$B$20:$O$31,5)-HLOOKUP(INT($AC24),$B$20:$O$31,5))*($AC24-INT($AC24)) -> 0.87 | AG24: =HLOOKUP(INT($AC24),$B$20:$O$31,6)+(HLOOKUP(INT($AC24)+1,$B$20:$O$31,6)-HLOOKUP(INT($AC24),$B$20:$O$31,6))*($AC24-INT($AC24)) -> 1 | AH24: =HLOOKUP(INT($AC24),$B$20:$O$31,7)+(HLOOKUP(INT($AC24)+1,$B$20:$O$31,7)-HLOOKUP(INT($AC24),$B$20:$O$31,7))*($AC24-INT($AC24)) -> 1.174 | AI24: =HLOOKUP(INT($AC24),$B$20:$O$31,8)+(HLOOKUP(INT($AC24)+1,$B$20:$O$31,8)-HLOOKUP(INT($AC24),$B$20:$O$31,8))*($AC24-INT($AC24)) -> 1.217 | AJ24: =HLOOKUP(INT($AC24),$B$20:$O$31,9)+(HLOOKUP(INT($AC24)+1,$B$20:$O$31,9)-HLOOKUP(INT($AC24),$B$20:$O$31,9))*($AC24-INT($AC24)) -> 1.391 | AK24: =HLOOKUP(INT($AC24),$B$20:$O$31,10)+(HLOOKUP(INT($AC24)+1,$B$20:$O$31,10)-HLOOKUP(INT($AC24),$B$20:$O$31,10))*($AC24-INT($AC24)) -> 1.652 | AM24: 참고조건1 | AN24: =INT(AN21) -> 0 | AO24: =INT(AO21) -> 0 | AP24: =INT(AP21) -> 0 | AQ24: =INT(AQ21) -> 0 | AR24: =INT(AR21) -> 0 | AS24: =INT(AS21) -> 0 | AT24: =INT(AT21) -> 0 | AU24: =INT(AU21) -> 0
A25: 40 | B25: =C25 -> 0.522 | C25: 0.522 | D25: =(C25+E25)/2 -> 0.5655 | E25: 0.609 | F25: =(E25+G25)/2 -> 0.696 | G25: 0.783 | H25: =(G25+I25)/2 -> 0.8915 | I25: 1 | J25: =(I25+K25)/2 -> 1.1085 | K25: 1.217 | L25: =(K25+M25)/2 -> 1.3475 | M25: 1.478 | N25: =(M25+O25)/2 -> 1.6085 | O25: 1.739 | Q25: 5구간 | R25: =R11 -> 0 | S25: =HLOOKUP(INT($R25),$B$20:$O$31,3)+(HLOOKUP(INT($R25)+1,$B$20:$O$31,3)-HLOOKUP(INT($R25),$B$20:$O$31,3))*($R25-INT($R25)) -> 0.652 | T25: =HLOOKUP(INT($R25),$B$20:$O$31,4)+(HLOOKUP(INT($R25)+1,$B$20:$O$31,4)-HLOOKUP(INT($R25),$B$20:$O$31,4))*($R25-INT($R25)) -> 0.783 | U25: =HLOOKUP(INT($R25),$B$20:$O$31,5)+(HLOOKUP(INT($R25)+1,$B$20:$O$31,5)-HLOOKUP(INT($R25),$B$20:$O$31,5))*($R25-INT($R25)) -> 0.87 | V25: =HLOOKUP(INT($R25),$B$20:$O$31,6)+(HLOOKUP(INT($R25)+1,$B$20:$O$31,6)-HLOOKUP(INT($R25),$B$20:$O$31,6))*($R25-INT($R25)) -> 1 | W25: =HLOOKUP(INT($R25),$B$20:$O$31,7)+(HLOOKUP(INT($R25)+1,$B$20:$O$31,7)-HLOOKUP(INT($R25),$B$20:$O$31,7))*($R25-INT($R25)) -> 1.174 | X25: =HLOOKUP(INT($R25),$B$20:$O$31,8)+(HLOOKUP(INT($R25)+1,$B$20:$O$31,8)-HLOOKUP(INT($R25),$B$20:$O$31,8))*($R25-INT($R25)) -> 1.217 | Y25: =HLOOKUP(INT($R25),$B$20:$O$31,9)+(HLOOKUP(INT($R25)+1,$B$20:$O$31,9)-HLOOKUP(INT($R25),$B$20:$O$31,9))*($R25-INT($R25)) -> 1.391 | Z25: =HLOOKUP(INT($R25),$B$20:$O$31,10)+(HLOOKUP(INT($R25)+1,$B$20:$O$31,10)-HLOOKUP(INT($R25),$B$20:$O$31,10))*($R25-INT($R25)) -> 1.652 | AB25: 5구간 | AC25: =AC11 -> 0 | AD25: =HLOOKUP(INT($AC25),$B$20:$O$31,3)+(HLOOKUP(INT($AC25)+1,$B$20:$O$31,3)-HLOOKUP(INT($AC25),$B$20:$O$31,3))*($AC25-INT($AC25)) -> 0.652 | AE25: =HLOOKUP(INT($AC25),$B$20:$O$31,4)+(HLOOKUP(INT($AC25)+1,$B$20:$O$31,4)-HLOOKUP(INT($AC25),$B$20:$O$31,4))*($AC25-INT($AC25)) -> 0.783 | AF25: =HLOOKUP(INT($AC25),$B$20:$O$31,5)+(HLOOKUP(INT($AC25)+1,$B$20:$O$31,5)-HLOOKUP(INT($AC25),$B$20:$O$31,5))*($AC25-INT($AC25)) -> 0.87 | AG25: =HLOOKUP(INT($AC25),$B$20:$O$31,6)+(HLOOKUP(INT($AC25)+1,$B$20:$O$31,6)-HLOOKUP(INT($AC25),$B$20:$O$31,6))*($AC25-INT($AC25)) -> 1 | AH25: =HLOOKUP(INT($AC25),$B$20:$O$31,7)+(HLOOKUP(INT($AC25)+1,$B$20:$O$31,7)-HLOOKUP(INT($AC25),$B$20:$O$31,7))*($AC25-INT($AC25)) -> 1.174 | AI25: =HLOOKUP(INT($AC25),$B$20:$O$31,8)+(HLOOKUP(INT($AC25)+1,$B$20:$O$31,8)-HLOOKUP(INT($AC25),$B$20:$O$31,8))*($AC25-INT($AC25)) -> 1.217 | AJ25: =HLOOKUP(INT($AC25),$B$20:$O$31,9)+(HLOOKUP(INT($AC25)+1,$B$20:$O$31,9)-HLOOKUP(INT($AC25),$B$20:$O$31,9))*($AC25-INT($AC25)) -> 1.391 | AK25: =HLOOKUP(INT($AC25),$B$20:$O$31,10)+(HLOOKUP(INT($AC25)+1,$B$20:$O$31,10)-HLOOKUP(INT($AC25),$B$20:$O$31,10))*($AC25-INT($AC25)) -> 1.652 | AM25: 참고값1 | AN25: =HLOOKUP(AN24,$B$20:$O$31,AN28) -> 0.652 | AO25: =HLOOKUP(AO24,$B$20:$O$31,AO28) -> 0.783 | AP25: =HLOOKUP(AP24,$B$20:$O$31,AP28) -> 0.87 | AQ25: =HLOOKUP(AQ24,$B$20:$O$31,AQ28) -> 1 | AR25: =HLOOKUP(AR24,$B$20:$O$31,AR28) -> 1.174 | AS25: =HLOOKUP(AS24,$B$20:$O$31,AS28) -> 1.217 | AT25: =HLOOKUP(AT24,$B$20:$O$31,AT28) -> 1.391 | AU25: =HLOOKUP(AU24,$B$20:$O$31,AU28) -> 1.652
A26: 50 | B26: =C26 -> 0.522 | C26: 0.522 | D26: =(C26+E26)/2 -> 0.587 | E26: 0.652 | F26: =(E26+G26)/2 -> 0.761 | G26: 0.87 | H26: =(G26+I26)/2 -> 1.022 | I26: 1.174 | J26: =(I26+K26)/2 -> 1.326 | K26: 1.478 | L26: =(K26+M26)/2 -> 1.652 | M26: 1.826 | N26: =(M26+O26)/2 -> 1.9565 | O26: 2.087 | Q26: 6구간 | R26: =R12 -> 0 | S26: =HLOOKUP(INT($R26),$B$20:$O$31,3)+(HLOOKUP(INT($R26)+1,$B$20:$O$31,3)-HLOOKUP(INT($R26),$B$20:$O$31,3))*($R26-INT($R26)) -> 0.652 | T26: =HLOOKUP(INT($R26),$B$20:$O$31,4)+(HLOOKUP(INT($R26)+1,$B$20:$O$31,4)-HLOOKUP(INT($R26),$B$20:$O$31,4))*($R26-INT($R26)) -> 0.783 | U26: =HLOOKUP(INT($R26),$B$20:$O$31,5)+(HLOOKUP(INT($R26)+1,$B$20:$O$31,5)-HLOOKUP(INT($R26),$B$20:$O$31,5))*($R26-INT($R26)) -> 0.87 | V26: =HLOOKUP(INT($R26),$B$20:$O$31,6)+(HLOOKUP(INT($R26)+1,$B$20:$O$31,6)-HLOOKUP(INT($R26),$B$20:$O$31,6))*($R26-INT($R26)) -> 1 | W26: =HLOOKUP(INT($R26),$B$20:$O$31,7)+(HLOOKUP(INT($R26)+1,$B$20:$O$31,7)-HLOOKUP(INT($R26),$B$20:$O$31,7))*($R26-INT($R26)) -> 1.174 | X26: =HLOOKUP(INT($R26),$B$20:$O$31,8)+(HLOOKUP(INT($R26)+1,$B$20:$O$31,8)-HLOOKUP(INT($R26),$B$20:$O$31,8))*($R26-INT($R26)) -> 1.217 | Y26: =HLOOKUP(INT($R26),$B$20:$O$31,9)+(HLOOKUP(INT($R26)+1,$B$20:$O$31,9)-HLOOKUP(INT($R26),$B$20:$O$31,9))*($R26-INT($R26)) -> 1.391 | Z26: =HLOOKUP(INT($R26),$B$20:$O$31,10)+(HLOOKUP(INT($R26)+1,$B$20:$O$31,10)-HLOOKUP(INT($R26),$B$20:$O$31,10))*($R26-INT($R26)) -> 1.652 | AB26: 6구간 | AC26: =AC12 -> 0 | AD26: =HLOOKUP(INT($AC26),$B$20:$O$31,3)+(HLOOKUP(INT($AC26)+1,$B$20:$O$31,3)-HLOOKUP(INT($AC26),$B$20:$O$31,3))*($AC26-INT($AC26)) -> 0.652 | AE26: =HLOOKUP(INT($AC26),$B$20:$O$31,4)+(HLOOKUP(INT($AC26)+1,$B$20:$O$31,4)-HLOOKUP(INT($AC26),$B$20:$O$31,4))*($AC26-INT($AC26)) -> 0.783 | AF26: =HLOOKUP(INT($AC26),$B$20:$O$31,5)+(HLOOKUP(INT($AC26)+1,$B$20:$O$31,5)-HLOOKUP(INT($AC26),$B$20:$O$31,5))*($AC26-INT($AC26)) -> 0.87 | AG26: =HLOOKUP(INT($AC26),$B$20:$O$31,6)+(HLOOKUP(INT($AC26)+1,$B$20:$O$31,6)-HLOOKUP(INT($AC26),$B$20:$O$31,6))*($AC26-INT($AC26)) -> 1 | AH26: =HLOOKUP(INT($AC26),$B$20:$O$31,7)+(HLOOKUP(INT($AC26)+1,$B$20:$O$31,7)-HLOOKUP(INT($AC26),$B$20:$O$31,7))*($AC26-INT($AC26)) -> 1.174 | AI26: =HLOOKUP(INT($AC26),$B$20:$O$31,8)+(HLOOKUP(INT($AC26)+1,$B$20:$O$31,8)-HLOOKUP(INT($AC26),$B$20:$O$31,8))*($AC26-INT($AC26)) -> 1.217 | AJ26: =HLOOKUP(INT($AC26),$B$20:$O$31,9)+(HLOOKUP(INT($AC26)+1,$B$20:$O$31,9)-HLOOKUP(INT($AC26),$B$20:$O$31,9))*($AC26-INT($AC26)) -> 1.391 | AK26: =HLOOKUP(INT($AC26),$B$20:$O$31,10)+(HLOOKUP(INT($AC26)+1,$B$20:$O$31,10)-HLOOKUP(INT($AC26),$B$20:$O$31,10))*($AC26-INT($AC26)) -> 1.652 | AM26: 참고조건2 | AN26: =AN24+1 -> 1 | AO26: =AO24+1 -> 1 | AP26: =AP24+1 -> 1 | AQ26: =AQ24+1 -> 1 | AR26: =AR24+1 -> 1 | AS26: =AS24+1 -> 1 | AT26: =AT24+1 -> 1 | AU26: =AU24+1 -> 1
A27: 60 | B27: =C27 -> 0.565 | C27: 0.565 | D27: =(C27+E27)/2 -> 0.6305 | E27: 0.696 | F27: =(E27+G27)/2 -> 0.8045 | G27: 0.913 | H27: =(G27+I27)/2 -> 1.065 | I27: 1.217 | J27: =(I27+K27)/2 -> 1.4345 | K27: 1.652 | L27: =(K27+M27)/2 -> 1.891 | M27: 2.13 | N27: =(M27+O27)/2 -> 2.3695 | O27: 2.609 | Q27: 7구간 | R27: =R13 -> 0 | S27: =HLOOKUP(INT($R27),$B$20:$O$31,3)+(HLOOKUP(INT($R27)+1,$B$20:$O$31,3)-HLOOKUP(INT($R27),$B$20:$O$31,3))*($R27-INT($R27)) -> 0.652 | T27: =HLOOKUP(INT($R27),$B$20:$O$31,4)+(HLOOKUP(INT($R27)+1,$B$20:$O$31,4)-HLOOKUP(INT($R27),$B$20:$O$31,4))*($R27-INT($R27)) -> 0.783 | U27: =HLOOKUP(INT($R27),$B$20:$O$31,5)+(HLOOKUP(INT($R27)+1,$B$20:$O$31,5)-HLOOKUP(INT($R27),$B$20:$O$31,5))*($R27-INT($R27)) -> 0.87 | V27: =HLOOKUP(INT($R27),$B$20:$O$31,6)+(HLOOKUP(INT($R27)+1,$B$20:$O$31,6)-HLOOKUP(INT($R27),$B$20:$O$31,6))*($R27-INT($R27)) -> 1 | W27: =HLOOKUP(INT($R27),$B$20:$O$31,7)+(HLOOKUP(INT($R27)+1,$B$20:$O$31,7)-HLOOKUP(INT($R27),$B$20:$O$31,7))*($R27-INT($R27)) -> 1.174 | X27: =HLOOKUP(INT($R27),$B$20:$O$31,8)+(HLOOKUP(INT($R27)+1,$B$20:$O$31,8)-HLOOKUP(INT($R27),$B$20:$O$31,8))*($R27-INT($R27)) -> 1.217 | Y27: =HLOOKUP(INT($R27),$B$20:$O$31,9)+(HLOOKUP(INT($R27)+1,$B$20:$O$31,9)-HLOOKUP(INT($R27),$B$20:$O$31,9))*($R27-INT($R27)) -> 1.391 | Z27: =HLOOKUP(INT($R27),$B$20:$O$31,10)+(HLOOKUP(INT($R27)+1,$B$20:$O$31,10)-HLOOKUP(INT($R27),$B$20:$O$31,10))*($R27-INT($R27)) -> 1.652 | AB27: 7구간 | AC27: =AC13 -> 0 | AD27: =HLOOKUP(INT($AC27),$B$20:$O$31,3)+(HLOOKUP(INT($AC27)+1,$B$20:$O$31,3)-HLOOKUP(INT($AC27),$B$20:$O$31,3))*($AC27-INT($AC27)) -> 0.652 | AE27: =HLOOKUP(INT($AC27),$B$20:$O$31,4)+(HLOOKUP(INT($AC27)+1,$B$20:$O$31,4)-HLOOKUP(INT($AC27),$B$20:$O$31,4))*($AC27-INT($AC27)) -> 0.783 | AF27: =HLOOKUP(INT($AC27),$B$20:$O$31,5)+(HLOOKUP(INT($AC27)+1,$B$20:$O$31,5)-HLOOKUP(INT($AC27),$B$20:$O$31,5))*($AC27-INT($AC27)) -> 0.87 | AG27: =HLOOKUP(INT($AC27),$B$20:$O$31,6)+(HLOOKUP(INT($AC27)+1,$B$20:$O$31,6)-HLOOKUP(INT($AC27),$B$20:$O$31,6))*($AC27-INT($AC27)) -> 1 | AH27: =HLOOKUP(INT($AC27),$B$20:$O$31,7)+(HLOOKUP(INT($AC27)+1,$B$20:$O$31,7)-HLOOKUP(INT($AC27),$B$20:$O$31,7))*($AC27-INT($AC27)) -> 1.174 | AI27: =HLOOKUP(INT($AC27),$B$20:$O$31,8)+(HLOOKUP(INT($AC27)+1,$B$20:$O$31,8)-HLOOKUP(INT($AC27),$B$20:$O$31,8))*($AC27-INT($AC27)) -> 1.217 | AJ27: =HLOOKUP(INT($AC27),$B$20:$O$31,9)+(HLOOKUP(INT($AC27)+1,$B$20:$O$31,9)-HLOOKUP(INT($AC27),$B$20:$O$31,9))*($AC27-INT($AC27)) -> 1.391 | AK27: =HLOOKUP(INT($AC27),$B$20:$O$31,10)+(HLOOKUP(INT($AC27)+1,$B$20:$O$31,10)-HLOOKUP(INT($AC27),$B$20:$O$31,10))*($AC27-INT($AC27)) -> 1.652 | AM27: 참고값2 | AN27: =HLOOKUP(AN26,$B$20:$O$31,AN28) -> 0.674 | AO27: =HLOOKUP(AO26,$B$20:$O$31,AO28) -> 0.8265 | AP27: =HLOOKUP(AP26,$B$20:$O$31,AP28) -> 0.935 | AQ27: =HLOOKUP(AQ26,$B$20:$O$31,AQ28) -> 1.1085 | AR27: =HLOOKUP(AR26,$B$20:$O$31,AR28) -> 1.326 | AS27: =HLOOKUP(AS26,$B$20:$O$31,AS28) -> 1.4345 | AT27: =HLOOKUP(AT26,$B$20:$O$31,AT28) -> 1.6305 | AU27: =HLOOKUP(AU26,$B$20:$O$31,AU28) -> 1.978
A28: 70 | B28: =C28 -> 0.565 | C28: 0.565 | D28: =(C28+E28)/2 -> 0.674 | E28: 0.783 | F28: =(E28+G28)/2 -> 0.935 | G28: 1.087 | H28: =(G28+I28)/2 -> 1.239 | I28: 1.391 | J28: =(I28+K28)/2 -> 1.6305 | K28: 1.87 | L28: =(K28+M28)/2 -> 2.087 | M28: 2.304 | N28: =(M28+O28)/2 -> 2.6735 | O28: 3.043 | Q28: 8구간 | R28: =R14 -> 0 | S28: =HLOOKUP(INT($R28),$B$20:$O$31,3)+(HLOOKUP(INT($R28)+1,$B$20:$O$31,3)-HLOOKUP(INT($R28),$B$20:$O$31,3))*($R28-INT($R28)) -> 0.652 | T28: =HLOOKUP(INT($R28),$B$20:$O$31,4)+(HLOOKUP(INT($R28)+1,$B$20:$O$31,4)-HLOOKUP(INT($R28),$B$20:$O$31,4))*($R28-INT($R28)) -> 0.783 | U28: =HLOOKUP(INT($R28),$B$20:$O$31,5)+(HLOOKUP(INT($R28)+1,$B$20:$O$31,5)-HLOOKUP(INT($R28),$B$20:$O$31,5))*($R28-INT($R28)) -> 0.87 | V28: =HLOOKUP(INT($R28),$B$20:$O$31,6)+(HLOOKUP(INT($R28)+1,$B$20:$O$31,6)-HLOOKUP(INT($R28),$B$20:$O$31,6))*($R28-INT($R28)) -> 1 | W28: =HLOOKUP(INT($R28),$B$20:$O$31,7)+(HLOOKUP(INT($R28)+1,$B$20:$O$31,7)-HLOOKUP(INT($R28),$B$20:$O$31,7))*($R28-INT($R28)) -> 1.174 | X28: =HLOOKUP(INT($R28),$B$20:$O$31,8)+(HLOOKUP(INT($R28)+1,$B$20:$O$31,8)-HLOOKUP(INT($R28),$B$20:$O$31,8))*($R28-INT($R28)) -> 1.217 | Y28: =HLOOKUP(INT($R28),$B$20:$O$31,9)+(HLOOKUP(INT($R28)+1,$B$20:$O$31,9)-HLOOKUP(INT($R28),$B$20:$O$31,9))*($R28-INT($R28)) -> 1.391 | Z28: =HLOOKUP(INT($R28),$B$20:$O$31,10)+(HLOOKUP(INT($R28)+1,$B$20:$O$31,10)-HLOOKUP(INT($R28),$B$20:$O$31,10))*($R28-INT($R28)) -> 1.652 | AB28: 8구간 | AC28: =AC14 -> 0 | AD28: =HLOOKUP(INT($AC28),$B$20:$O$31,3)+(HLOOKUP(INT($AC28)+1,$B$20:$O$31,3)-HLOOKUP(INT($AC28),$B$20:$O$31,3))*($AC28-INT($AC28)) -> 0.652 | AE28: =HLOOKUP(INT($AC28),$B$20:$O$31,4)+(HLOOKUP(INT($AC28)+1,$B$20:$O$31,4)-HLOOKUP(INT($AC28),$B$20:$O$31,4))*($AC28-INT($AC28)) -> 0.783 | AF28: =HLOOKUP(INT($AC28),$B$20:$O$31,5)+(HLOOKUP(INT($AC28)+1,$B$20:$O$31,5)-HLOOKUP(INT($AC28),$B$20:$O$31,5))*($AC28-INT($AC28)) -> 0.87 | AG28: =HLOOKUP(INT($AC28),$B$20:$O$31,6)+(HLOOKUP(INT($AC28)+1,$B$20:$O$31,6)-HLOOKUP(INT($AC28),$B$20:$O$31,6))*($AC28-INT($AC28)) -> 1 | AH28: =HLOOKUP(INT($AC28),$B$20:$O$31,7)+(HLOOKUP(INT($AC28)+1,$B$20:$O$31,7)-HLOOKUP(INT($AC28),$B$20:$O$31,7))*($AC28-INT($AC28)) -> 1.174 | AI28: =HLOOKUP(INT($AC28),$B$20:$O$31,8)+(HLOOKUP(INT($AC28)+1,$B$20:$O$31,8)-HLOOKUP(INT($AC28),$B$20:$O$31,8))*($AC28-INT($AC28)) -> 1.217 | AJ28: =HLOOKUP(INT($AC28),$B$20:$O$31,9)+(HLOOKUP(INT($AC28)+1,$B$20:$O$31,9)-HLOOKUP(INT($AC28),$B$20:$O$31,9))*($AC28-INT($AC28)) -> 1.391 | AK28: =HLOOKUP(INT($AC28),$B$20:$O$31,10)+(HLOOKUP(INT($AC28)+1,$B$20:$O$31,10)-HLOOKUP(INT($AC28),$B$20:$O$31,10))*($AC28-INT($AC28)) -> 1.652 | AN28: 3 | AO28: 4 | AP28: 5 | AQ28: 6 | AR28: 7 | AS28: 8 | AT28: 9 | AU28: 10
A29: 80 | B29: =C29 -> 0.565 | C29: 0.565 | D29: =(C29+E29)/2 -> 0.6955 | E29: 0.826 | F29: =(E29+G29)/2 -> 1.0215 | G29: 1.217 | H29: =(G29+I29)/2 -> 1.4345 | I29: 1.652 | J29: =(I29+K29)/2 -> 1.978 | K29: 2.304 | L29: =(K29+M29)/2 -> 2.587 | M29: 2.87 | N29: =(M29+O29)/2 -> 3.3045 | O29: 3.739 | Q29: 9구간 | R29: =R15 -> 0 | S29: =HLOOKUP(INT($R29),$B$20:$O$31,3)+(HLOOKUP(INT($R29)+1,$B$20:$O$31,3)-HLOOKUP(INT($R29),$B$20:$O$31,3))*($R29-INT($R29)) -> 0.652 | T29: =HLOOKUP(INT($R29),$B$20:$O$31,4)+(HLOOKUP(INT($R29)+1,$B$20:$O$31,4)-HLOOKUP(INT($R29),$B$20:$O$31,4))*($R29-INT($R29)) -> 0.783 | U29: =HLOOKUP(INT($R29),$B$20:$O$31,5)+(HLOOKUP(INT($R29)+1,$B$20:$O$31,5)-HLOOKUP(INT($R29),$B$20:$O$31,5))*($R29-INT($R29)) -> 0.87 | V29: =HLOOKUP(INT($R29),$B$20:$O$31,6)+(HLOOKUP(INT($R29)+1,$B$20:$O$31,6)-HLOOKUP(INT($R29),$B$20:$O$31,6))*($R29-INT($R29)) -> 1 | W29: =HLOOKUP(INT($R29),$B$20:$O$31,7)+(HLOOKUP(INT($R29)+1,$B$20:$O$31,7)-HLOOKUP(INT($R29),$B$20:$O$31,7))*($R29-INT($R29)) -> 1.174 | X29: =HLOOKUP(INT($R29),$B$20:$O$31,8)+(HLOOKUP(INT($R29)+1,$B$20:$O$31,8)-HLOOKUP(INT($R29),$B$20:$O$31,8))*($R29-INT($R29)) -> 1.217 | Y29: =HLOOKUP(INT($R29),$B$20:$O$31,9)+(HLOOKUP(INT($R29)+1,$B$20:$O$31,9)-HLOOKUP(INT($R29),$B$20:$O$31,9))*($R29-INT($R29)) -> 1.391 | Z29: =HLOOKUP(INT($R29),$B$20:$O$31,10)+(HLOOKUP(INT($R29)+1,$B$20:$O$31,10)-HLOOKUP(INT($R29),$B$20:$O$31,10))*($R29-INT($R29)) -> 1.652 | AB29: 9구간 | AC29: =AC15 -> 0 | AD29: =HLOOKUP(INT($AC29),$B$20:$O$31,3)+(HLOOKUP(INT($AC29)+1,$B$20:$O$31,3)-HLOOKUP(INT($AC29),$B$20:$O$31,3))*($AC29-INT($AC29)) -> 0.652 | AE29: =HLOOKUP(INT($AC29),$B$20:$O$31,4)+(HLOOKUP(INT($AC29)+1,$B$20:$O$31,4)-HLOOKUP(INT($AC29),$B$20:$O$31,4))*($AC29-INT($AC29)) -> 0.783 | AF29: =HLOOKUP(INT($AC29),$B$20:$O$31,5)+(HLOOKUP(INT($AC29)+1,$B$20:$O$31,5)-HLOOKUP(INT($AC29),$B$20:$O$31,5))*($AC29-INT($AC29)) -> 0.87 | AG29: =HLOOKUP(INT($AC29),$B$20:$O$31,6)+(HLOOKUP(INT($AC29)+1,$B$20:$O$31,6)-HLOOKUP(INT($AC29),$B$20:$O$31,6))*($AC29-INT($AC29)) -> 1 | AH29: =HLOOKUP(INT($AC29),$B$20:$O$31,7)+(HLOOKUP(INT($AC29)+1,$B$20:$O$31,7)-HLOOKUP(INT($AC29),$B$20:$O$31,7))*($AC29-INT($AC29)) -> 1.174 | AI29: =HLOOKUP(INT($AC29),$B$20:$O$31,8)+(HLOOKUP(INT($AC29)+1,$B$20:$O$31,8)-HLOOKUP(INT($AC29),$B$20:$O$31,8))*($AC29-INT($AC29)) -> 1.217 | AJ29: =HLOOKUP(INT($AC29),$B$20:$O$31,9)+(HLOOKUP(INT($AC29)+1,$B$20:$O$31,9)-HLOOKUP(INT($AC29),$B$20:$O$31,9))*($AC29-INT($AC29)) -> 1.391 | AK29: =HLOOKUP(INT($AC29),$B$20:$O$31,10)+(HLOOKUP(INT($AC29)+1,$B$20:$O$31,10)-HLOOKUP(INT($AC29),$B$20:$O$31,10))*($AC29-INT($AC29)) -> 1.652
